File: src/parser/__tests__/data/assigned.vms
VAMAS Surface Chemical Analysis Standard Data Transfer Format 1988 May 4
Not specified
MI-600-BE9240AA
DESKTOP-MI6NA2R\kratos
20200903_RW_WS2MoS2_XPS.experiment
13
Casa Info Follows CasaXPS Version 2.3.22PR1.0
2
Mo 3d
Mo 3d
Nb 3d
Nb 3d
SourceAnalyserAngle: 54.735600 d
CasaRowLabel:RW_WS2_MoS2_thicker
CasaRowLabel:RW_WS2
CasaRowLabel:RW_Tha_MoS2
CasaRowLabel:RW_sonic_MoS2
CasaRowLabel:RW_WS2_MoS2
CasaRowLabel:RW_Nb_MoS2
NORM
REGULAR
9
4
Index
d
PositionX [mm]
n
PositionY [mm]
n
PositionZ [mm]
n
0
0
0
0
54
wide
RW_WS2_MoS2_thicker
2020
9
3
16
20
21
2
46
Casa Info Follows
2
Calib M = 281.1700 A = 284.8 BE ADD
Calib M = 284.7999 A = 284.8 BE ADD
0
0
0
Creation
Created by : DESKTOP-MI6NA2R\kratos
Date created : 03/09/2020 16:20
Computer : DESKTOP-MI6NA2R
Location
Location ID : RW_WS2_MoS2_thicker
Sample : RW_WS2_MoS2_thicker
Description : (6.422,19.568,-1.679)mm
Tilt : 0.00
Charge Neutraliser : On
Filament Current : 0.45A
Filament Bias : 1V
Charge Balance : 4.9V
Settings
Excitation
Mode : XPS - monochromatic
Tuning : Spectroscopy
Emission current : 15.00mA
Anode library : Al
ESCA modes
Collimation : Slot
Lens : Hybrid
Resolution : 160.00
Scan
Deflection : (0.000, 0.000)mm
wide : 286.690-1491.690eV, Sweeps 1
Start : 286.690eV
End : 1491.690eV
Centre : 889.190eV
Width : 1205.000eV
Step size : 1.000eV
Number Steps : 1205
Dwell time : 100ms
Sweep time : 120s
Sweeps : 1
Instrument Conditions
Work function : -4.50
Acquisition Conditions
X-ray Power : 225.00W
XPS
1
6.4215
19.5681
-1.67878
Al (mono)
1486.69
225
1e+037
1e+037
1e+037
1e+037
FAT
160
1e+037
-4.5
1e+037
1e+037
1e+037
1e+037
1e+037
wide

-1
Kinetic energy
eV
286.69
1
2
Intensity
d
Transmission
d
pulse counting
0.0995025
0
1e+037
0
9
12.1975
17427
17573
17408
17538
17659
17660
17815
17702
17722
17783
17841
18008
18022
17961
17910
17917
18241
18227
18129
18099
18159
18334
18503
18458
18294
18412
18439
18636
18549
18666
18570
18769
18935
18880
18835
19242
19056
18821
18932
19017
19279
19297
19309
19184
19317
19374
19294
19391
19683
19639
19858
19752
19548
19948
19749
19944
19823
20021
20228
20042
19829
19877
20251
20309
20167
20320
20475
20662
20546
20552
20641
20277
20352
20446
20568
20527
20696
20778
20764
20812
20822
20957
20913
21269
21007
21112
21030
21117
21149
21180
21289
21141
21304
21383
21316
21348
21504
21719
21839
21654
21634
21391
21548
21686
21556
21374
20973
21012
21095
21193
21175
21216
21176
21300
21361
21487
21432
21385
21390
21432
21639
21429
21330
21829
21860
21939
22004
21874
21768
21798
22088
22275
22455
22413
22263
22225
22294
22114
22273
22524
22580
22438
22727
22753
22738
22917
22658
22741
22917
23296
23123
22861
23175
23152
23084
23281
23479
23259
23195
23412
23293
23452
23525
23769
23654
23508
23594
23945
23910
24001
24154
24316
24385
24491
24514
24347
24602
24502
24696
24822
24931
25049
25151
25205
25074
25293
25503
25492
25680
25598
25616
25553
25825
25525
25725
25831
26072
25942
26339
26495
26573
27202
27574
27572
27695
27346
27364
27288
27096
27225
26664
26629
26031
25877
25617
25526
25272
25127
25311
25213
25419
26015
27182
27703
28841
29895
30378
30672
30678
30454
29771
28898
28036
27104
25584
24445
23204
22181
21500
21025
20823
20604
20542
20403
20422
20298
20426
20510
20528
20219
20149
20359
20545
20452
20489
20505
20430
20505
20547
20707
20729
20918
20579
20528
20646
20653
20836
20797
20918
20758
20846
20702
20835
20797
20999
21004
21067
21006
21055
21036
20956
21032
21212
21010
20983
20911
21101
21211
21237
21396
21108
21126
21335
21561
21433
21630
21399
21538
21433
21532
21532
21686
21856
21685
21720
21783
21658
21714
21811
22027
21950
21664
21855
22069
22110
21766
21801
21905
21940
21885
22195
22191
22199
22199
22114
22355
22132
22230
22443
22500
22157
22064
22317
22370
22340
22165
22526
22648
22725
22593
22655
22788
22502
22558
22773
22628
22700
22701
22860
22884
22931
22907
22972
22990
22773
23030
23120
23024
23143
23148
23062
22815
23148
23184
23480
23245
23109
23079
23125
23282
23382
23373
23567
23310
23343
23595
23715
23519
23393
23381
23547
23412
23879
23935
23835
23698
23654
23931
23872
23812
23825
23807
23818
24111
23933
23839
23938
24029
23708
23986
24208
24094
23930
24196
24494
24022
24101
24144
24093
24111
24412
24524
24548
24583
24249
24130
24280
24490
24292
24343
24376
24457
24403
24444
24408
24564
24409
24702
24537
24547
24396
24528
24853
24887
24850
24850
24823
24846
25233
25096
25065
25105
24934
24976
25122
25185
25246
25145
25130
25313
25410
25311
25022
25237
25027
25053
25200
25441
25290
25320
25285
25387
25436
25439
25472
25669
25748
25597
25785
25928
25568
25432
25473
25467
25832
25808
25657
26048
25686
25744
25728
25983
25812
25988
25893
25996
26218
26231
25935
26014
26072
26162
26252
26048
26130
25980
26291
26258
26141
26186
26318
26512
26176
26413
26182
26216
26270
26525
26455
26395
26415
26704
26650
26553
26628
26434
26629
26928
26580
26519
26848
26716
26774
26671
26878
26868
26974
27114
26759
26841
26895
26983
26893
27237
26971
27059
27264
27224
27276
27303
27252
27304
27232
27294
27416
27151
27401
27567
27640
27372
27556
27274
27511
27430
27426
27376
27663
27857
27586
27616
27524
27909
27733
27578
27465
27651
27638
27829
27864
27893
27862
28089
27939
28116
28052
27782
27901
28058
28050
28058
28084
28087
28071
28208
28182
28144
28221
28265
28251
28200
28444
28571
28475
28460
28577
28562
28468
28308
28549
28637
28760
28986
28876
28973
28802
29247
28908
28825
28715
28939
29048
28785
28763
28972
29126
28874
28752
28986
28854
29076
28892
28966
29189
29199
29205
29089
29077
29015
28952
29122
28767
29025
29062
29019
29216
29102
28665
28925
29026
29187
29151
29240
29618
29632
29379
29653
30008
30082
30029
29927
30056
29624
29391
29255
28718
28721
28513
28484
28419
27771
26967
26567
26486
26036
25752
25992
26351
26369
26780
29125
36258
49804
60653
53843
36015
26155
23771
23396
23307
23043
23110
23028
22877
22811
22626
22953
22765
22841
22644
22642
22718
22728
22818
22792
22720
22611
22743
22491
22175
22423
22292
22431
21967
22402
22288
22010
22443
22797
23100
23396
22683
22231
22135
22113
21960
22058
22665
23186
23087
22303
21741
21756
21420
21631
21563
21406
21774
21884
21945
21792
21674
21692
21684
21528
22022
21777
21745
21629
21651
21639
21598
21678
21572
21579
21637
21528
21570
21853
21555
21562
21297
21482
21645
21674
21700
21850
21757
21599
21608
21723
21559
21377
21367
21413
21569
21639
21494
21580
21517
21237
21458
21297
21460
21766
21835
21814
22130
22220
22204
21724
21689
21363
21285
21238
21035
21119
20861
20980
20929
20777
20754
20758
20406
20297
19852
19479
19369
19257
19111
19179
19346
20722
22973
26460
27602
24255
20934
19719
20056
20066
19559
18879
18747
18519
18518
18402
18527
18580
18439
18314
18302
18564
18408
18289
18562
18627
18585
18424
18289
18481
18197
18390
18445
18298
18348
18518
18518
18729
18666
18599
18555
18584
18631
18476
18600
18681
18650
18741
18676
18846
18538
18561
18700
18773
18679
18673
18717
18961
18818
18719
18845
18907
18667
18723
18897
18860
19085
18822
18821
18707
18719
18508
18786
18794
18843
18917
18804
18799
18711
18688
18630
18857
18851
18814
18660
18753
18809
18945
18916
18879
19017
18991
19040
18999
18950
18818
18605
18568
18474
18448
18138
17711
17160
17031
16748
16373
16214
16185
15817
15575
15367
15490
15775
15846
17549
22196
25969
28806
34808
36742
27175
16952
13513
12995
12979
12835
12688
12573
12433
12391
12373
12071
12015
11946
11828
11773
11741
11636
11457
11410
11252
11441
11739
11976
11884
11899
11722
11636
11551
11471
10854
10727
10641
10716
10769
10823
11056
11025
10598
10009
9545
8985
8599
8068
7722
7689
7659
7927
8157
8206
8729
10418
10884
8978
9084
9822
8511
7643
7514
6986
6376
6010
5923
5903
5785
5769
5699
5772
5708
5652
5717
5712
5583
5606
5654
5583
5514
5454
5566
5365
5367
5420
5382
5409
5385
5308
5268
5260
5255
5332
5371
5261
5331
5311
5326
5460
5465
5409
5328
5270
5237
5118
5100
4969
4847
4813
4648
4561
4605
4454
4472
4408
4482
4601
5154
5843
5689
4878
4543
4477
5047
6124
6469
5152
4082
3931
3989
3898
3850
3994
4038
4170
3989
3931
3777
3821
3854
3800
3718
3709
3777
3731
3714
3688
3692
3759
3724
3732
3702
3708
3655
3541
3687
3722
3576
3607
3613
3647
3643
3609
3556
3630
3566
3454
3471
3478
3454
3495
3487
3538
3503
3429
3443
3320
3415
3398
3353
3368
3374
3350
3451
3616
3721
3547
3404
3206
3213
3168
3179
3108
3175
3221
3089
3111
3200
3133
3185
3064
3131
3099
3030
3034
2975
2962
2986
3021
2966
2906
2856
2828
2767
2634
2590
2607
2654
2667
2652
2706
2553
2774
2741
2755
2761
2652
2625
2645
2637
2680
2610
2548
2468
2419
2333
2177
2105
2054
1855
1804
1793
1702
1672
1778
1756
1756
1867
2308
3201
3364
3668
3944
2872
2536
2229
1327
962
1108
1229
1496
1526
1321
1123
960
830
733
627
602
634
606
562
564
638
582
527
566
567
559
543
561
582
585
528
408
269
155
37
9
15.5208
O 1s
RW_WS2_MoS2_thicker
2020
9
3
17
7
49
2
48
Casa Info Follows
2
Calib M = 281.1700 A = 284.8 BE ADD
Calib M = 284.7999 A = 284.8 BE ADD
0
0
0
Creation
Created by : DESKTOP-MI6NA2R\kratos
Date created : 03/09/2020 17:07
Computer : DESKTOP-MI6NA2R
Location
Location ID : RW_WS2_MoS2_thicker
Sample : RW_WS2_MoS2_thicker
Description : (6.422,19.568,-1.679)mm
Tilt : 0.00
Charge Neutraliser : On
Filament Current : 0.45A
Filament Bias : 1V
Charge Balance : 4.9V
Settings
Excitation
Mode : XPS - monochromatic
Tuning : Spectroscopy
Emission current : 15.00mA
Anode library : Al
ESCA modes
Collimation : Slot
Lens : Hybrid
Resolution : 40.00
Scan
Deflection : (0.000, 0.000)mm
O 1s : 943.690-961.690eV, Sweeps 1
Start : 943.690eV
End : 961.690eV
Centre : 952.690eV
Width : 18.000eV
Step size : 0.150eV
Number Steps : 120
Dwell time : 496ms
Sweep time : 60s
Sweeps : 1
Target quality : 200
Instrument Conditions
Work function : -4.50
Acquisition Conditions
X-ray Power : 225.00W
Quality : 263.50
XPS
2
6.4215
19.5681
-1.67878
Al (mono)
1486.69
225
1e+037
1e+037
1e+037
1e+037
FAT
40
1e+037
-4.5
1e+037
1e+037
1e+037
1e+037
1e+037
O
1s
-1
Kinetic energy
eV
943.69
0.15
2
Intensity
d
Transmission
d
pulse counting
0.495868
1
0
1e+037
1e+037
1e+037
0
242
11753
38669
2.19746
2.20238
14398
2.20238
14585
2.20234
14408
2.20229
14482
2.20225
14288
2.20221
14344
2.20217
14385
2.20213
14299
2.20209
14240
2.20205
14137
2.20201
14031
2.20197
14055
2.20193
14065
2.20188
13994
2.20184
13992
2.2018
13826
2.20176
13651
2.20172
13806
2.20168
13671
2.20164
13516
2.2016
13219
2.20156
13363
2.20152
13572
2.20148
13495
2.20143
13343
2.20139
13246
2.20135
13381
2.20131
13518
2.20127
13233
2.20123
13347
2.20119
13350
2.20115
13321
2.20111
13283
2.20107
13133
2.20102
13078
2.20098
13132
2.20094
13159
2.2009
13071
2.20086
12887
2.20082
13028
2.20078
12845
2.20074
12804
2.2007
12862
2.20066
12840
2.20062
12676
2.20057
12733
2.20053
12856
2.20049
12979
2.20045
12891
2.20041
12826
2.20037
12778
2.20033
12809
2.20029
12760
2.20025
12935
2.20021
12866
2.20016
12937
2.20012
12833
2.20008
13019
2.20004
12854
2.2
12917
2.19996
12888
2.19992
12992
2.19988
12892
2.19984
12789
2.1998
12925
2.19975
13019
2.19971
13031
2.19967
12831
2.19963
12826
2.19959
12758
2.19955
12534
2.19951
12620
2.19947
12615
2.19943
12611
2.19939
12804
2.19935
12621
2.1993
12863
2.19926
12803
2.19922
12786
2.19918
12924
2.19914
13075
2.1991
13350
2.19906
13892
2.19902
14330
2.19898
14696
2.19894
15581
2.19889
16074
2.19885
16953
2.19881
17984
2.19877
19062
2.19873
20235
2.19869
21587
2.19865
22900
2.19861
24180
2.19857
26003
2.19853
27960
2.19849
29918
2.19844
31605
2.1984
33734
2.19836
36007
2.19832
37600
2.19828
38669
2.19824
38452
2.1982
37442
2.19816
35862
2.19812
33472
2.19808
30555
2.19803
27809
2.19799
25154
2.19795
22605
2.19791
20214
2.19787
18178
2.19783
16594
2.19779
15296
2.19775
14371
2.19771
13333
2.19767
12869
2.19763
12246
2.19758
12103
2.19754
11900
2.1975
11753
2.19746
C 1s
RW_WS2_MoS2_thicker
2020
9
3
17
7
49
2
49
Casa Info Follows
2
Calib M = 281.1700 A = 284.8 BE ADD
Calib M = 284.7999 A = 284.8 BE ADD
0
1
CASA region (*C 1s*) (*U 2 Tougaard*) 1193.9028 1205.0344 0.278 2 0 0 786.70222 -450 0 0 (*C 1s*) 12.011 0 0.278
0
Creation
Created by : DESKTOP-MI6NA2R\kratos
Date created : 03/09/2020 17:07
Computer : DESKTOP-MI6NA2R
Location
Location ID : RW_WS2_MoS2_thicker
Sample : RW_WS2_MoS2_thicker
Description : (6.422,19.568,-1.679)mm
Tilt : 0.00
Charge Neutraliser : On
Filament Current : 0.45A
Filament Bias : 1V
Charge Balance : 4.9V
Settings
Excitation
Mode : XPS - monochromatic
Tuning : Spectroscopy
Emission current : 15.00mA
Anode library : Al
ESCA modes
Collimation : Slot
Lens : Hybrid
Resolution : 40.00
Scan
Deflection : (0.000, 0.000)mm
C 1s : 1186.715-1209.665eV, Sweeps 1
Start : 1186.715eV
End : 1209.665eV
Centre : 1198.190eV
Width : 22.950eV
Step size : 0.150eV
Number Steps : 153
Dwell time : 390ms
Sweep time : 60s
Sweeps : 1
Target quality : 200
Instrument Conditions
Work function : -4.50
Acquisition Conditions
X-ray Power : 225.00W
Quality : 212.73
XPS
3
6.4215
19.5681
-1.67878
Al (mono)
1486.69
225
1e+037
1e+037
1e+037
1e+037
FAT
40
1e+037
-4.5
1e+037
1e+037
1e+037
1e+037
1e+037
C
1s
-1
Kinetic energy
eV
1186.715
0.15
2
Intensity
d
Transmission
d
pulse counting
0.38961
1
0
1e+037
1e+037
1e+037
2
ESCAPE DEPTH TYPE
d
1
MFP Exponent
d
0
308
4938
18386
2.14721
2.15079
7007
2.14816
7008
2.14812
7010
2.14808
7049
2.14803
7041
2.14799
6990
2.14794
6855
2.1479
6868
2.14786
6850
2.14781
6943
2.14777
6861
2.14773
6811
2.14768
6857
2.14764
6829
2.14759
6873
2.14755
6702
2.14751
6664
2.14746
6825
2.14742
6670
2.14737
6602
2.14733
6547
2.14729
6534
2.14724
6526
2.14721
6642
2.14723
6658
2.14726
6583
2.14729
6544
2.14732
6431
2.14734
6400
2.14737
6330
2.1474
6402
2.14742
6389
2.14745
6406
2.14748
6360
2.14751
6359
2.14753
6447
2.14756
6362
2.14759
6375
2.14762
6304
2.14764
6339
2.14767
6247
2.1477
6197
2.14773
6140
2.14775
6230
2.14778
6243
2.14781
6218
2.14784
6243
2.14786
6170
2.14789
6257
2.14792
6073
2.14794
6037
2.14797
6095
2.148
6072
2.14803
5995
2.14805
6117
2.14808
6071
2.14811
6037
2.14814
5949
2.14816
5894
2.14819
5990
2.14822
6071
2.14825
5938
2.14827
5893
2.1483
5777
2.14833
5907
2.14836
5838
2.14838
5863
2.14841
5897
2.14844
5968
2.14846
5832
2.14849
5771
2.14852
5928
2.14855
5993
2.14857
5926
2.1486
5938
2.14863
5850
2.14866
5925
2.14868
5924
2.14871
5886
2.14874
6014
2.14877
5884
2.14879
5909
2.14882
5857
2.14885
5935
2.14887
5983
2.1489
5975
2.14893
5979
2.14896
6025
2.14898
6019
2.14901
6024
2.14904
5908
2.14907
6073
2.14909
6073
2.14912
6263
2.14915
6480
2.14918
6652
2.1492
7071
2.14923
7454
2.14926
8032
2.14929
8658
2.14931
9079
2.14934
9705
2.14937
10324
2.14939
10816
2.14942
11023
2.14945
10933
2.14948
10730
2.1495
10475
2.14953
10078
2.14956
9865
2.14959
9637
2.14961
9498
2.14964
9675
2.14967
9882
2.1497
10451
2.14972
11123
2.14975
11849
2.14978
12584
2.14981
13495
2.14983
14092
2.14986
15020
2.14989
15612
2.14991
16365
2.14994
17002
2.14997
17773
2.15
18386
2.15002
18284
2.15005
17764
2.15008
16984
2.15011
15542
2.15013
13814
2.15016
12139
2.15019
10488
2.15022
9013
2.15024
7832
2.15027
6850
2.1503
6196
2.15032
5705
2.15035
5487
2.15038
5288
2.15041
5099
2.15043
5197
2.15046
5191
2.15049
5092
2.15052
5102
2.15054
5050
2.15057
5037
2.1506
5051
2.15063
5018
2.15065
5030
2.15068
4959
2.15071
4938
2.15074
5001
2.15076
5006
2.15079
Br 3d
RW_WS2_MoS2_thicker
2020
9
3
17
7
49
2
48
Casa Info Follows
2
Calib M = 281.1700 A = 284.8 BE ADD
Calib M = 284.7999 A = 284.8 BE ADD
0
0
0
Creation
Created by : DESKTOP-MI6NA2R\kratos
Date created : 03/09/2020 17:07
Computer : DESKTOP-MI6NA2R
Location
Location ID : RW_WS2_MoS2_thicker
Sample : RW_WS2_MoS2_thicker
Description : (6.422,19.568,-1.679)mm
Tilt : 0.00
Charge Neutraliser : On
Filament Current : 0.45A
Filament Bias : 1V
Charge Balance : 4.9V
Settings
Excitation
Mode : XPS - monochromatic
Tuning : Spectroscopy
Emission current : 15.00mA
Anode library : Al
ESCA modes
Collimation : Slot
Lens : Hybrid
Resolution : 40.00
Scan
Deflection : (0.000, 0.000)mm
Br 3d : 1408.715-1422.665eV, Sweeps 3
Start : 1408.715eV
End : 1422.665eV
Centre : 1415.690eV
Width : 13.950eV
Step size : 0.150eV
Number Steps : 93
Dwell time : 638ms
Sweep time : 60s
Sweeps : 3
Target quality : 200
Instrument Conditions
Work function : -4.50
Acquisition Conditions
X-ray Power : 225.00W
Quality : 19.12
XPS
4
6.4215
19.5681
-1.67878
Al (mono)
1486.69
225
1e+037
1e+037
1e+037
1e+037
FAT
40
1e+037
-4.5
1e+037
1e+037
1e+037
1e+037
1e+037
Br
3d
-1
Kinetic energy
eV
1408.715
0.15
2
Intensity
d
Transmission
d
pulse counting
0.638298
3
0
1e+037
1e+037
1e+037
0
188
5052
5995
2.13994
2.14675
5919
2.13994
5910
2.14001
5875
2.14008
5857
2.14016
5906
2.14023
5843
2.1403
5946
2.14037
5967
2.14045
5995
2.14052
5915
2.14059
5908
2.14067
5892
2.14074
5904
2.14081
5872
2.14089
5809
2.14096
5910
2.14103
5917
2.14111
5798
2.14118
5800
2.14125
5892
2.14133
5784
2.1414
5860
2.14147
5733
2.14155
5754
2.14162
5807
2.14169
5803
2.14177
5700
2.14184
5675
2.14191
5726
2.14199
5705
2.14206
5739
2.14213
5645
2.14221
5680
2.14228
5594
2.14235
5593
2.14243
5599
2.1425
5671
2.14257
5689
2.14265
5503
2.14272
5533
2.14279
5520
2.14287
5618
2.14294
5456
2.14301
5644
2.14309
5650
2.14316
5522
2.14323
5541
2.14331
5396
2.14338
5383
2.14345
5481
2.14353
5459
2.1436
5395
2.14367
5297
2.14375
5459
2.14382
5434
2.14389
5348
2.14397
5384
2.14404
5465
2.14411
5352
2.14419
5292
2.14426
5244
2.14433
5259
2.14441
5282
2.14448
5258
2.14455
5172
2.14463
5135
2.1447
5226
2.14477
5188
2.14485
5139
2.14492
5209
2.14499
5091
2.14507
5222
2.14514
5234
2.14521
5144
2.14529
5127
2.14536
5139
2.14543
5127
2.1455
5209
2.14558
5237
2.14565
5215
2.14572
5163
2.1458
5200
2.14587
5169
2.14594
5111
2.14602
5125
2.14609
5052
2.14616
5155
2.14624
5071
2.14631
5163
2.14638
5192
2.14646
5136
2.14653
5113
2.1466
5128
2.14668
5144
2.14675
Nb 3d
RW_WS2_MoS2_thicker
2020
9
3
17
7
49
2
48
Casa Info Follows
2
Calib M = 281.1700 A = 284.8 BE ADD
Calib M = 284.7999 A = 284.8 BE ADD
0
0
0
Creation
Created by : DESKTOP-MI6NA2R\kratos
Date created : 03/09/2020 17:07
Computer : DESKTOP-MI6NA2R
Location
Location ID : RW_WS2_MoS2_thicker
Sample : RW_WS2_MoS2_thicker
Description : (6.422,19.568,-1.679)mm
Tilt : 0.00
Charge Neutraliser : On
Filament Current : 0.45A
Filament Bias : 1V
Charge Balance : 4.9V
Settings
Excitation
Mode : XPS - monochromatic
Tuning : Spectroscopy
Emission current : 15.00mA
Anode library : Al
ESCA modes
Collimation : Slot
Lens : Hybrid
Resolution : 40.00
Scan
Deflection : (0.000, 0.000)mm
Nb 3d : 1271.715-1291.665eV, Sweeps 5
Start : 1271.715eV
End : 1291.665eV
Centre : 1281.690eV
Width : 19.950eV
Step size : 0.150eV
Number Steps : 133
Dwell time : 448ms
Sweep time : 60s
Sweeps : 5
Target quality : 200
Instrument Conditions
Work function : -4.50
Acquisition Conditions
X-ray Power : 225.00W
Quality : 17.66
XPS
6
6.4215
19.5681
-1.67878
Al (mono)
1486.69
225
1e+037
1e+037
1e+037
1e+037
FAT
40
1e+037
-4.5
1e+037
1e+037
1e+037
1e+037
1e+037
Nb
3d
-1
Kinetic energy
eV
1271.715
0.15
2
Intensity
d
Transmission
d
pulse counting
0.447761
5
0
1e+037
1e+037
1e+037
0
268
11940
13161
2.15405
2.15493
13161
2.15493
13107
2.15492
13021
2.15492
12918
2.15491
12916
2.1549
12979
2.1549
13022
2.15489
13001
2.15488
13041
2.15488
13016
2.15487
13021
2.15486
12889
2.15486
12812
2.15485
12783
2.15484
12798
2.15484
12878
2.15483
12947
2.15482
12982
2.15482
12936
2.15481
12916
2.1548
12908
2.1548
12940
2.15479
13004
2.15478
12890
2.15478
12966
2.15477
12946
2.15476
12821
2.15476
12705
2.15475
12836
2.15474
12851
2.15474
12929
2.15473
13076
2.15472
12828
2.15472
12976
2.15471
12872
2.1547
12966
2.1547
12841
2.15469
12809
2.15468
12859
2.15468
12762
2.15467
12781
2.15466
12819
2.15466
12808
2.15465
12848
2.15464
12896
2.15464
12648
2.15463
12871
2.15462
12679
2.15462
12628
2.15461
12731
2.15461
12921
2.1546
12863
2.15459
12876
2.15459
12768
2.15458
12746
2.15457
12860
2.15457
12818
2.15456
12903
2.15455
12735
2.15455
12762
2.15454
12737
2.15453
12719
2.15453
12572
2.15452
12784
2.15451
12773
2.15451
12844
2.1545
12660
2.15449
12804
2.15449
12722
2.15448
12535
2.15447
12503
2.15447
12598
2.15446
12631
2.15445
12585
2.15445
12608
2.15444
12745
2.15443
12686
2.15443
12661
2.15442
12579
2.15441
12624
2.15441
12584
2.1544
12615
2.15439
12542
2.15439
12580
2.15438
12570
2.15437
12436
2.15437
12629
2.15436
12521
2.15435
12457
2.15435
12547
2.15434
12477
2.15433
12558
2.15433
12491
2.15432
12401
2.15431
12357
2.15431
12579
2.1543
12528
2.1543
12524
2.15429
12373
2.15428
12425
2.15428
12473
2.15427
12376
2.15426
12478
2.15426
12416
2.15425
12378
2.15424
12371
2.15424
12249
2.15423
12196
2.15422
12136
2.15422
12369
2.15421
12284
2.1542
12212
2.1542
12272
2.15419
12384
2.15418
12445
2.15418
12141
2.15417
12309
2.15416
12239
2.15416
12096
2.15415
12132
2.15414
12128
2.15414
12386
2.15413
12152
2.15412
12188
2.15412
12255
2.15411
12335
2.1541
12179
2.1541
11940
2.15409
12203
2.15408
12234
2.15408
12084
2.15407
11968
2.15406
12069
2.15406
12166
2.15405
Mo 3d
RW_WS2_MoS2_thicker
2020
9
3
17
7
49
2
59
Casa Info Follows
2
Calib M = 281.1700 A = 284.8 BE ADD
Calib M = 284.7999 A = 284.8 BE ADD
0
1
CASA region (*Mo 3d*) (*Shirley*) 1249.3343 1262.7065 10.804667 2 0 0 392.54541 -450 0 0 (*Mo 3d*) 95.9219 0 9.5
10
CASA comp (*Mo 3d MoS2 2H*) (*LA(1.53,243)*) Area 230.36971 1e-020 2327991 -1 1 MFWHM 0.88528218 0.2 2 -1 1 Position 1257.22 1257.02 1257.22 -1 1 RSF 10.804667 MASS 95.9219 INDEX -1 (*Mo 3d*) CONST (**) UNCORRECTEDRSF 9.5
CASA comp (*Mo 3d MoS2 2H*) (*LA(1.53,243)*) Area 153.57981 1e-020 2327991 0 0.66666667 MFWHM 0.76493355 0.65389948 1.2538995 -1 1 Position 1254.08 0 0 0 -3.14 RSF 10.804667 MASS 95.9219 INDEX -1 (*Mo 3d*) CONST (**) UNCORRECTEDRSF 9.5
CASA comp (*Mo 3d MoS2 1T*) (*LA(1.53,243)*) Area 7955.3136 1e-020 2327991 -1 1 MFWHM 0.91171962 0.2533 1.5 -1 1 Position 1257.89 1257.89 1258.49 -1 1 RSF 10.804667 MASS 95.9219 INDEX -1 (*Mo 3d*) CONST (**) UNCORRECTEDRSF 9.5
CASA comp (*Mo 3d MoS2 1T*) (*LA(1.53,243)*) Area 5303.5425 1e-020 2327991 2 0.66666667 MFWHM 0.91171962 0.2532592 6.33148 2 1 Position 1254.75 0 0 2 -3.14 RSF 10.804667 MASS 95.9219 INDEX -1 (*Mo 3d*) CONST (**) UNCORRECTEDRSF 9.5
CASA comp (*Mo 3d MoO3*) (*LA(1.53,243)*) Area 1401.4078 1e-020 1384876 -1 1 MFWHM 0.99977143 0.285 2 -1 1 Position 1253.99 1253.39 1253.99 -1 1 RSF 10.804667 MASS 95.9219 INDEX -1 (*Mo 3d*) CONST (**) UNCORRECTEDRSF 9.5
CASA comp (*S 2s*) (*LA(1.53,243)*) Area 3602.311 1e-020 2327991 -1 1 MFWHM 1.7375263 0.20524482 5.1311205 -1 1 Position 1260.5811 1258.0143 1262.0143 -1 1 RSF 10.804667 MASS 95.9219 INDEX -1 (*Mo 3d*) CONST (**) UNCORRECTEDRSF 9.5
CASA comp (*Mo 3d MoO2*) (*LA(1.53,243)*) Area 863.91709 1e-020 2327991 -1 1 MFWHM 1.0329112 0.2949 2 -1 1 Position 1255.8573 1255.8573 1256.4573 -1 1 RSF 10.804667 MASS 95.9219 INDEX -1 (*Mo 3d*) CONST (**) UNCORRECTEDRSF 9.5
CASA comp (*Mo 3d MoO2*) (*LA(1.53,243)*) Area 575.94473 1e-020 2327991 6 0.66666667 MFWHM 1.0329112 0.2949286 7.3732149 6 1 Position 1252.7173 0 0 6 -3.14 RSF 10.804667 MASS 95.9219 INDEX -1 (*Mo 3d*) CONST (**) UNCORRECTEDRSF 9.5
CASA comp (*Mo 3d MoO3*) (*LA(1.53,243)*) Area 2669.5646 1e-020 2327991 -1 1 MFWHM 1.4420932 0.2537 2 -1 1 Position 1254.5622 1253.615 1254.69 -1 1 RSF 10.804667 MASS 95.9219 INDEX -1 (*Mo 3d*) CONST (**) UNCORRECTEDRSF 9.5
CASA comp (*Mo 3d MoO3*) (*LA(1.53,243)*) Area 1779.7097 1e-020 2327991 8 0.66666667 MFWHM 1.4420932 0.25368427 6.3421067 8 1 Position 1251.4222 0 0 8 -3.14 RSF 10.804667 MASS 95.9219 INDEX -1 (*Mo 3d*) CONST (**) UNCORRECTEDRSF 9.5
Creation
Created by : DESKTOP-MI6NA2R\kratos
Date created : 03/09/2020 17:07
Computer : DESKTOP-MI6NA2R
Location
Location ID : RW_WS2_MoS2_thicker
Sample : RW_WS2_MoS2_thicker
Description : (6.422,19.568,-1.679)mm
Tilt : 0.00
Charge Neutraliser : On
Filament Current : 0.45A
Filament Bias : 1V
Charge Balance : 4.9V
Settings
Excitation
Mode : XPS - monochromatic
Tuning : Spectroscopy
Emission current : 15.00mA
Anode library : Al
ESCA modes
Collimation : Slot
Lens : Hybrid
Resolution : 40.00
Scan
Deflection : (0.000, 0.000)mm
Mo 3d : 1246.715-1266.665eV, Sweeps 6
Start : 1246.715eV
End : 1266.665eV
Centre : 1256.690eV
Width : 19.950eV
Step size : 0.150eV
Number Steps : 133
Dwell time : 448ms
Sweep time : 60s
Sweeps : 6
Target quality : 300
Instrument Conditions
Work function : -4.50
Acquisition Conditions
X-ray Power : 225.00W
Quality : 113.50
XPS
8
6.4215
19.5681
-1.67878
Al (mono)
1486.69
225
1e+037
1e+037
1e+037
1e+037
FAT
40
1e+037
-4.5
1e+037
1e+037
1e+037
1e+037
1e+037
Mo
3d
-1
Kinetic energy
eV
1246.715
0.15
2
Intensity
d
Transmission
d
pulse counting
0.44776
6
0
1e+037
1e+037
1e+037
3
ESCAPE DEPTH TYPE
d
1
MFP Exponent
d
0
PROPAGATION_CONVERGED
d
1
268
16577
39798
2.15515
2.15603
26223
2.15603
25924
2.15602
25555
2.15601
25254
2.15601
24575
2.156
24676
2.15599
24459
2.15599
24125
2.15598
23739
2.15597
23696
2.15597
23238
2.15596
23149
2.15596
22918
2.15595
22638
2.15594
22420
2.15594
22281
2.15593
22402
2.15592
22021
2.15592
21996
2.15591
21809
2.1559
21532
2.1559
21486
2.15589
21338
2.15588
21299
2.15588
21062
2.15587
20933
2.15586
21048
2.15586
20992
2.15585
20982
2.15584
20850
2.15584
20760
2.15583
20911
2.15582
20751
2.15582
20539
2.15581
20843
2.1558
20696
2.1558
20474
2.15579
20544
2.15578
20549
2.15578
20513
2.15577
20421
2.15576
20231
2.15576
20321
2.15575
20162
2.15574
20463
2.15574
20276
2.15573
20498
2.15572
20674
2.15572
20667
2.15571
21117
2.1557
21561
2.1557
21931
2.15569
22653
2.15568
22957
2.15568
22868
2.15567
23111
2.15566
23184
2.15566
22906
2.15565
22505
2.15565
21983
2.15564
22005
2.15563
21862
2.15563
21678
2.15562
21541
2.15561
21663
2.15561
21585
2.1556
21661
2.15559
21739
2.15559
22475
2.15558
22969
2.15557
24006
2.15557
25617
2.15556
27353
2.15555
29057
2.15555
32042
2.15554
34818
2.15553
37187
2.15553
38177
2.15552
37549
2.15551
35402
2.15551
32272
2.1555
29257
2.15549
26611
2.15549
24621
2.15548
23118
2.15547
21852
2.15547
21110
2.15546
20200
2.15545
19657
2.15545
19599
2.15544
19396
2.15543
19282
2.15543
19857
2.15542
21148
2.15541
23106
2.15541
26529
2.1554
31867
2.15539
36910
2.15539
39798
2.15538
38918
2.15537
35144
2.15537
30217
2.15536
25779
2.15535
22622
2.15535
20772
2.15534
19340
2.15534
19056
2.15533
18568
2.15532
18807
2.15532
18985
2.15531
19400
2.1553
19944
2.1553
20566
2.15529
21177
2.15528
21328
2.15528
21876
2.15527
22197
2.15526
22027
2.15526
21716
2.15525
21527
2.15524
20857
2.15524
20398
2.15523
19631
2.15522
18849
2.15522
18580
2.15521
18335
2.1552
17801
2.1552
17429
2.15519
17179
2.15518
17039
2.15518
16750
2.15517
16673
2.15516
16601
2.15516
16577
2.15515
W 4f
RW_WS2_MoS2_thicker
2020
9
3
17
7
49
2
57
Casa Info Follows
2
Calib M = 281.1700 A = 284.8 BE ADD
Calib M = 284.7999 A = 284.8 BE ADD
0
1
CASA region (*W 4f*) (*Shirley*) 1446.874 1455.9097 11.364733 2 0 0 2622.1736 -450 0 0 (*W 4f*) 183.847 0 9.8
8
CASA comp (*W 4f WSe2*) (*LA(2.5,2.8,70)*) Area 2709.2313 1e-020 265247.75 -1 1 MFWHM 0.70766798 0.2 5 -1 1 Position 1454.4025 1453.69 1454.49 -1 1 RSF 9.8 MASS 183.847 INDEX -1 (*W 4f*) CONST (**) UNCORRECTEDRSF 9.8
CASA comp (*W 4f WSe2*) (*LA(2.5,2.8,70)*) Area 2031.9235 1e-020 265247.75 0 0.75 MFWHM 0.70766798 0.2 5 0 1 Position 1452.3225 0 0 0 -2.08 RSF 9.8 MASS 183.847 INDEX -1 (*W 4f*) CONST (**) UNCORRECTEDRSF 9.8
CASA comp (*W 4f WO3*) (*GL(40)*) Area 5019.8908 1e-020 123349.01 -1 1 MFWHM 1.2728662 0.5 3 -1 1 Position 1451.3323 1449.69 1451.69 -1 1 RSF 9.8 MASS 183.847 INDEX -1 (*W 4f*) CONST (**) UNCORRECTEDRSF 9.8
CASA comp (*W 4f WO3*) (*GL(40)*) Area 3764.9181 1e-020 123349.01 2 0.75 MFWHM 1.2728662 0.257653 6.441325 2 1 Position 1449.1823 0 0 2 -2.15 RSF 9.8 MASS 183.847 INDEX -1 (*W 4f*) CONST (**) UNCORRECTEDRSF 9.8
CASA comp (*W 4d WSe2*) (*GL(40)*) Area 224.05343 0 5000 0 0.0827 MFWHM 2.3131698 2.1131698 2.3131698 -1 1 Position 1448.5164 0 0 0 -5.8861 RSF 9.8 MASS 183.847 INDEX -1 (*W 4f*) CONST (**) UNCORRECTEDRSF 9.8
CASA comp (*W 4f W(0)*) (*LA(1.3,2.5,11)*) Area 693.70012 0 50000 -1 1 MFWHM 0.47924931 0.2 0.8 -1 1 Position 1454.8883 1454.59 1455.39 -1 1 RSF 9.8 MASS 183.847 INDEX -1 (*W 4f*) CONST (**) UNCORRECTEDRSF 9.8
CASA comp (*W 4f W(0)*) (*LA(1.3,2.5,11)*) Area 520.27509 1e-020 265247.75 5 0.75 MFWHM 0.47924931 0.2 5 5 1 Position 1452.7883 0 0 5 -2.1 RSF 9.8 MASS 183.847 INDEX -1 (*W 4f*) CONST (**) UNCORRECTEDRSF 9.8
CASA comp (*W 4d W(0)*) (*GL(40)*) Area 57.369 0 5000 5 0.0827 MFWHM 2.1131698 2.1131698 2.3131698 -1 1 Position 1449.0022 0 0 5 -5.8861 RSF 9.8 MASS 183.847 INDEX -1 (*W 4f*) CONST (**) UNCORRECTEDRSF 9.8
Creation
Created by : DESKTOP-MI6NA2R\kratos
Date created : 03/09/2020 17:07
Computer : DESKTOP-MI6NA2R
Location
Location ID : RW_WS2_MoS2_thicker
Sample : RW_WS2_MoS2_thicker
Description : (6.422,19.568,-1.679)mm
Tilt : 0.00
Charge Neutraliser : On
Filament Current : 0.45A
Filament Bias : 1V
Charge Balance : 4.9V
Settings
Excitation
Mode : XPS - monochromatic
Tuning : Spectroscopy
Emission current : 15.00mA
Anode library : Al
ESCA modes
Collimation : Slot
Lens : Hybrid
Resolution : 40.00
Scan
Deflection : (0.000, 0.000)mm
W 4f : 1441.715-1461.665eV, Sweeps 6
Start : 1441.715eV
End : 1461.665eV
Centre : 1451.690eV
Width : 19.950eV
Step size : 0.150eV
Number Steps : 133
Dwell time : 448ms
Sweep time : 60s
Sweeps : 6
Target quality : 200
Instrument Conditions
Work function : -4.50
Acquisition Conditions
X-ray Power : 225.00W
Quality : 100.18
XPS
9
6.4215
19.5681
-1.67878
Al (mono)
1486.69
225
1e+037
1e+037
1e+037
1e+037
FAT
40
1e+037
-4.5
1e+037
1e+037
1e+037
1e+037
1e+037
W
4f
-1
Kinetic energy
eV
1441.715
0.15
2
Intensity
d
Transmission
d
pulse counting
0.44776
6
0
1e+037
1e+037
1e+037
3
ESCAPE DEPTH TYPE
d
1
MFP Exponent
d
0
PROPAGATION_CONVERGED
d
1
268
2292
13549
2.15606
2.16581
5579
2.15606
5515
2.15613
5437
2.1562
5375
2.15628
5286
2.15635
5239
2.15642
5234
2.1565
5265
2.15657
5113
2.15664
5084
2.15672
5199
2.15679
5068
2.15686
4982
2.15694
5065
2.15701
4958
2.15708
4952
2.15716
4850
2.15723
4897
2.1573
4814
2.15738
4860
2.15745
4844
2.15752
4677
2.1576
4716
2.15767
4754
2.15774
4749
2.15782
4680
2.15789
4668
2.15796
4630
2.15804
4693
2.15811
4696
2.15818
4642
2.15826
4720
2.15833
4563
2.1584
4647
2.15848
4614
2.15855
4563
2.15862
4681
2.1587
4731
2.15877
4704
2.15884
4740
2.15892
4732
2.15899
4722
2.15906
4748
2.15914
4871
2.15921
4923
2.15928
4942
2.15936
4980
2.15943
4973
2.1595
5044
2.15958
4976
2.15965
4986
2.15972
4968
2.1598
4941
2.15987
4895
2.15994
4935
2.16002
4919
2.16009
4878
2.16016
4937
2.16024
4932
2.16031
4921
2.16038
4890
2.16046
4999
2.16053
4945
2.1606
4968
2.16068
5076
2.16075
5327
2.16082
5720
2.16089
6219
2.16097
7046
2.16104
7927
2.16111
8934
2.16119
10172
2.16126
11296
2.16133
11933
2.16141
12115
2.16148
11700
2.16155
10918
2.16163
9748
2.1617
8729
2.16177
7827
2.16185
7391
2.16192
7291
2.16199
7457
2.16207
8240
2.16214
9209
2.16221
10635
2.16229
12008
2.16236
13032
2.16243
13549
2.16251
13255
2.16258
12675
2.16265
12293
2.16273
12261
2.1628
12753
2.16287
12844
2.16295
12387
2.16302
10964
2.16309
8862
2.16317
6819
2.16324
5283
2.16331
4094
2.16339
3413
2.16346
3146
2.16353
3211
2.16361
3859
2.16368
5056
2.16375
6812
2.16383
9509
2.1639
11678
2.16397
12604
2.16405
11784
2.16412
9914
2.16419
7771
2.16427
5625
2.16434
4111
2.16441
3180
2.16449
2700
2.16456
2413
2.16463
2330
2.16471
2292
2.16478
2342
2.16485
2352
2.16493
2374
2.165
2383
2.16507
2435
2.16515
2461
2.16522
2463
2.16529
2460
2.16537
2474
2.16544
2521
2.16551
2644
2.16559
2611
2.16566
2676
2.16573
2869
2.16581
1: S 2p
RW_WS2_MoS2_thicker
2020
9
3
21
56
7
2
53
Casa Info Follows
2
Calib M = 281.1700 A = 284.8 BE ADD
Calib M = 284.7999 A = 284.8 BE ADD
0
1
CASA region (*S 2p*) (*U 2 Tougaard*) 1320.746 1327.3909 0.66800007 2 0 0 2684.4128 -450 0 0 (*S 2p*) 32.0648 0 0.668
4
CASA comp (*S 2p WS2*) (*GL(30)*) Area 273.10085 1e-020 291645.06 -1 1 MFWHM 1 0.5 1 -1 1 Position 1323.9177 1323.9177 1324.1177 -1 1 RSF 0.66800007 MASS 32.0648 INDEX -1 (*S 2p*) CONST (**) UNCORRECTEDRSF 0.668
CASA comp (*S 2p WS2*) (*GL(30)*) Area 136.55042 1e-020 291645.06 0 0.5 MFWHM 1 0.2 5 0 1 Position 1322.7577 0 0 0 -1.16 RSF 0.66800007 MASS 32.0648 INDEX -1 (*S 2p*) CONST (**) UNCORRECTEDRSF 0.668
CASA comp (*S 2p MoS2*) (*GL(30)*) Area 5317.9403 1e-020 291645.06 -1 1 MFWHM 0.89879457 0.2 5 -1 1 Position 1324.9322 1324.7223 1325.1223 -1 1 RSF 0.66800007 MASS 32.0648 INDEX -1 (*S 2p*) CONST (**) UNCORRECTEDRSF 0.668
CASA comp (*S 2p MoS2*) (*GL(30)*) Area 2658.9701 1e-020 291645.06 2 0.5 MFWHM 0.89879457 0.2 5 2 1 Position 1323.7722 0 0 2 -1.16 RSF 0.66800007 MASS 32.0648 INDEX -1 (*S 2p*) CONST (**) UNCORRECTEDRSF 0.668
Creation
Created by : DESKTOP-MI6NA2R\kratos
Date created : 03/09/2020 21:56
Computer : DESKTOP-MI6NA2R
Location
Location ID : RW_WS2_MoS2_thicker
Sample : RW_WS2_MoS2_thicker
Description : (6.422,19.568,-1.679)mm
Tilt : 0.00
Charge Neutraliser : On
Filament Current : 0.45A
Filament Bias : 1V
Charge Balance : 4.9V
Settings
Excitation
Mode : XPS - monochromatic
Tuning : Spectroscopy
Emission current : 15.00mA
Anode library : Al
ESCA modes
Collimation : Slot
Lens : Hybrid
Resolution : 40.00
Scan
Deflection : (0.000, 0.000)mm
S 2p : 1314.715-1334.665eV, Sweeps 5
Start : 1314.715eV
End : 1334.665eV
Centre : 1324.690eV
Width : 19.950eV
Step size : 0.150eV
Number Steps : 133
Dwell time : 448ms
Sweep time : 60s
Sweeps : 5
Target quality : 300
Instrument Conditions
Work function : -4.50
Acquisition Conditions
X-ray Power : 225.00W
Quality : 109.24
XPS
10
6.4215
19.5681
-1.67878
Al (mono)
1486.69
225
1e+037
1e+037
1e+037
1e+037
FAT
40
1e+037
-4.5
1e+037
1e+037
1e+037
1e+037
1e+037
S
2p
-1
Kinetic energy
eV
1314.715
0.15
2
Intensity
d
Transmission
d
pulse counting
0.447761
5
0
1e+037
1e+037
1e+037
1
PROPAGATION_CONVERGED
d
1
268
8745
21457
2.12923
2.1433
10219
2.1433
10365
2.1432
10302
2.14309
10315
2.14299
10326
2.14288
10280
2.14277
10225
2.14267
10228
2.14256
10266
2.14246
10167
2.14235
10247
2.14225
10247
2.14214
10355
2.14203
10304
2.14193
10378
2.14182
10344
2.14172
10250
2.14161
10286
2.14151
10178
2.1414
10144
2.14129
10266
2.14119
10240
2.14108
10326
2.14098
10227
2.14087
10125
2.14076
10235
2.14066
10261
2.14055
10188
2.14045
10152
2.14034
10254
2.14024
10244
2.14013
10127
2.14002
10205
2.13992
10433
2.13981
10581
2.13971
10549
2.1396
10853
2.13949
11354
2.13939
11679
2.13928
12176
2.13918
12396
2.13907
12715
2.13897
13397
2.13886
13334
2.13875
13823
2.13865
14079
2.13854
14218
2.13844
14692
2.13833
15052
2.13822
15231
2.13812
15252
2.13801
14945
2.13791
14306
2.1378
13602
2.1377
12753
2.13759
11846
2.13748
11451
2.13738
11169
2.13727
10708
2.13717
10494
2.13706
10085
2.13696
10040
2.13685
9859
2.13674
9836
2.13664
9826
2.13653
9768
2.13643
9841
2.13632
9820
2.13621
9782
2.13611
9800
2.136
9878
2.1359
9926
2.13579
9703
2.13569
9851
2.13558
9772
2.13547
9876
2.13537
10044
2.13526
10106
2.13516
10170
2.13505
10403
2.13494
11179
2.13484
12252
2.13473
13571
2.13463
14940
2.13452
15808
2.13442
15664
2.13431
15204
2.1342
14455
2.1341
14420
2.13399
15797
2.13389
17910
2.13378
20066
2.13367
21457
2.13357
20644
2.13346
18729
2.13336
16034
2.13325
13593
2.13315
11650
2.13304
10363
2.13293
9694
2.13283
9203
2.13272
9325
2.13262
9330
2.13251
9253
2.13241
9176
2.1323
8978
2.13219
8980
2.13209
8941
2.13198
8926
2.13188
8821
2.13177
8830
2.13166
8985
2.13156
8926
2.13145
8862
2.13135
8978
2.13124
8814
2.13114
8975
2.13103
8873
2.13092
8931
2.13082
9052
2.13071
8969
2.13061
8804
2.1305
8745
2.13039
8876
2.13029
8824
2.13018
8816
2.13008
9011
2.12997
9078
2.12987
8882
2.12976
8948
2.12965
8891
2.12955
8898
2.12944
8991
2.12934
9029
2.12923
1: N 1s
RW_WS2_MoS2_thicker
2020
9
4
14
28
59
2
48
Casa Info Follows
2
Calib M = 281.1700 A = 284.8 BE ADD
Calib M = 284.7999 A = 284.8 BE ADD
0
0
0
Creation
Created by : DESKTOP-MI6NA2R\kratos
Date created : 04/09/2020 14:28
Computer : DESKTOP-MI6NA2R
Location
Location ID : RW_WS2_MoS2_thicker
Sample : RW_WS2_MoS2_thicker
Description : (6.422,19.568,-1.679)mm
Tilt : 0.00
Charge Neutraliser : On
Filament Current : 0.45A
Filament Bias : 1V
Charge Balance : 4.9V
Settings
Excitation
Mode : XPS - monochromatic
Tuning : Spectroscopy
Emission current : 15.00mA
Anode library : Al
ESCA modes
Collimation : Slot
Lens : Hybrid
Resolution : 40.00
Scan
Deflection : (0.000, 0.000)mm
N 1s : 1071.690-1101.690eV, Sweeps 5
Start : 1071.690eV
End : 1101.690eV
Centre : 1086.690eV
Width : 30.000eV
Step size : 0.150eV
Number Steps : 200
Dwell time : 299ms
Sweep time : 60s
Sweeps : 5
Target quality : 300
Instrument Conditions
Work function : -4.50
Acquisition Conditions
X-ray Power : 225.00W
Quality : 174.44
XPS
11
6.4215
19.5681
-1.67878
Al (mono)
1486.69
225
1e+037
1e+037
1e+037
1e+037
FAT
40
1e+037
-4.5
1e+037
1e+037
1e+037
1e+037
1e+037
N
1s
-1
Kinetic energy
eV
1071.69
0.15
2
Intensity
d
Transmission
d
pulse counting
0.298507
5
0
1e+037
1e+037
1e+037
0
402
26555
47090
2.1702
2.17351
30775
2.1702
30826
2.17022
30983
2.17023
30959
2.17025
30814
2.17027
30824
2.17029
30900
2.1703
31025
2.17032
30897
2.17034
30731
2.17036
30639
2.17038
30774
2.17039
30817
2.17041
30898
2.17043
30896
2.17045
31040
2.17046
30665
2.17048
30928
2.1705
30941
2.17052
30747
2.17053
30774
2.17055
30815
2.17057
31050
2.17059
30849
2.1706
30719
2.17062
30907
2.17064
30800
2.17066
30820
2.17067
30505
2.17069
30492
2.17071
30464
2.17073
30561
2.17075
30477
2.17076
30309
2.17078
30391
2.1708
30573
2.17082
30738
2.17083
31010
2.17085
30720
2.17087
30727
2.17089
30854
2.1709
30796
2.17092
30913
2.17094
31045
2.17096
31033
2.17097
30883
2.17099
30542
2.17101
30428
2.17103
30180
2.17104
29995
2.17106
30002
2.17108
29690
2.1711
29476
2.17112
29414
2.17113
29437
2.17115
29302
2.17117
29220
2.17119
29198
2.1712
28735
2.17122
28978
2.17124
28807
2.17126
28869
2.17127
28788
2.17129
28649
2.17131
28834
2.17133
28869
2.17134
28783
2.17136
28516
2.17138
28745
2.1714
28442
2.17142
28530
2.17143
28385
2.17145
28317
2.17147
28456
2.17149
28269
2.1715
28346
2.17152
28403
2.17154
28095
2.17156
28181
2.17157
28332
2.17159
28318
2.17161
28282
2.17163
28011
2.17164
28092
2.17166
28319
2.17168
28483
2.1717
28351
2.17171
28311
2.17173
28007
2.17175
27988
2.17177
28126
2.17179
28114
2.1718
28119
2.17182
28130
2.17184
28229
2.17186
28069
2.17187
28217
2.17189
28214
2.17191
28057
2.17193
28185
2.17194
28183
2.17196
28246
2.17198
28108
2.172
28138
2.17201
28119
2.17203
28387
2.17205
28520
2.17207
29123
2.17208
29703
2.1721
29976
2.17212
30520
2.17214
31042
2.17216
31815
2.17217
32561
2.17219
32850
2.17221
33211
2.17223
34035
2.17224
34754
2.17226
36335
2.17228
37265
2.1723
38855
2.17231
40872
2.17233
42937
2.17235
45059
2.17237
46321
2.17238
47003
2.1724
47090
2.17242
45627
2.17244
43885
2.17246
41675
2.17247
39627
2.17249
37363
2.17251
35478
2.17253
34037
2.17254
32850
2.17256
31825
2.17258
30951
2.1726
30617
2.17261
29875
2.17263
29396
2.17265
29327
2.17267
29208
2.17268
28901
2.1727
28797
2.17272
28809
2.17274
28951
2.17275
28650
2.17277
28560
2.17279
28825
2.17281
28800
2.17283
28900
2.17284
28939
2.17286
28842
2.17288
29021
2.1729
29129
2.17291
29578
2.17293
29946
2.17295
30157
2.17297
30231
2.17298
30420
2.173
30260
2.17302
29850
2.17304
29966
2.17305
29778
2.17307
29109
2.17309
28982
2.17311
28719
2.17312
28657
2.17314
28471
2.17316
28296
2.17318
28107
2.1732
28025
2.17321
27662
2.17323
27510
2.17325
27567
2.17327
27447
2.17328
27150
2.1733
27396
2.17332
27329
2.17334
27235
2.17335
27160
2.17337
27360
2.17339
27050
2.17341
26902
2.17342
26739
2.17344
26874
2.17346
27097
2.17348
27087
2.1735
26877
2.17351
26764
2.17351
27072
2.17347
27152
2.17343
26851
2.17338
26555
2.17334
27011
2.17329
27017
2.17325
26896
2.17321
27075
2.17316
26945
2.17312
26769
2.17308
26693
2.17303
wide
RW_WS2
2020
9
3
16
24
31
2
47
Casa Info Follows
3
Calib M = 281.1700 A = 284.8 BE ADD
Calib M = 284.3712 A = 285.09 BE ADD
Calib M = 285.0898 A = 284.8 BE ADD
0
0
0
Creation
Created by : DESKTOP-MI6NA2R\kratos
Date created : 03/09/2020 16:24
Computer : DESKTOP-MI6NA2R
Location
Location ID : RW_WS2
Sample : RW_WS2
Description : (31.777,5.746,-2.057)mm
Tilt : 0.00
Charge Neutraliser : On
Filament Current : 0.45A
Filament Bias : 1V
Charge Balance : 4.9V
Settings
Excitation
Mode : XPS - monochromatic
Tuning : Spectroscopy
Emission current : 15.00mA
Anode library : Al
ESCA modes
Collimation : Slot
[...]
Creation
Created by : DESKTOP-MI6NA2R\kratos
Date created : 03/09/2020 21:07
Computer : DESKTOP-MI6NA2R
Location
Location ID : RW_Nb_MoS2
Sample : RW_Nb_MoS2
Description : (32.368,22.987,-1.908)mm
Tilt : 0.00
Charge Neutraliser : On
Filament Current : 0.45A
Filament Bias : 1V
Charge Balance : 4.9V
Settings
Excitation
Mode : XPS - monochromatic
Tuning : Spectroscopy
Emission current : 15.00mA
Anode library : Al
ESCA modes
Collimation : Slot
Lens : Hybrid
Resolution : 40.00
Scan
Deflection : (0.000, 0.000)mm
Nb 3d : 1271.715-1291.665eV, Sweeps 5
Start : 1271.715eV
End : 1291.665eV
Centre : 1281.690eV
Width : 19.950eV
Step size : 0.150eV
Number Steps : 133
Dwell time : 448ms
Sweep time : 60s
Sweeps : 5
Target quality : 200
Instrument Conditions
Work function : -4.50
Acquisition Conditions
X-ray Power : 225.00W
Quality : 20.01
XPS
61
32.368
22.9871
-1.90798
Al (mono)
1486.69
225
1e+037
1e+037
1e+037
1e+037
FAT
40
1e+037
-4.5
1e+037
1e+037
1e+037
1e+037
1e+037
Nb
3d
-1
Kinetic energy
eV
1271.715
0.15
2
Intensity
d
Transmission
d
pulse counting
0.447761
5
0
1e+037
1e+037
1e+037
1
PROPAGATION_CONVERGED
d
1
268
22801
24861
2.15405
2.15493
23406
2.15493
23196
2.15492
23494
2.15492
23432
2.15491
23347
2.1549
23202
2.1549
23271
2.15489
23437
2.15488
23455
2.15488
23172
2.15487
23464
2.15486
23123
2.15486
23206
2.15485
23442
2.15484
23359
2.15484
23268
2.15483
23188
2.15482
23243
2.15482
23339
2.15481
23317
2.1548
23189
2.1548
23290
2.15479
23534
2.15478
23406
2.15478
23428
2.15477
23328
2.15476
23277
2.15476
23209
2.15475
23360
2.15474
23256
2.15474
23206
2.15473
23209
2.15472
23535
2.15472
23474
2.15471
23351
2.1547
23375
2.1547
23383
2.15469
23365
2.15468
23194
2.15468
23432
2.15467
23167
2.15466
23261
2.15466
23415
2.15465
23495
2.15464
23369
2.15464
23492
2.15463
23424
2.15462
23577
2.15462
23283
2.15461
23573
2.15461
23613
2.1546
23648
2.15459
23852
2.15459
23913
2.15458
23792
2.15457
24029
2.15457
24349
2.15456
24339
2.15455
24336
2.15455
24284
2.15454
24465
2.15453
24227
2.15453
24096
2.15452
23979
2.15451
23707
2.15451
23554
2.1545
23594
2.15449
23586
2.15449
23775
2.15448
23711
2.15447
23746
2.15447
24030
2.15446
23881
2.15445
24055
2.15445
24569
2.15444
24627
2.15443
24856
2.15443
24861
2.15442
24731
2.15441
24796
2.15441
24667
2.1544
24277
2.15439
24208
2.15439
24161
2.15438
23888
2.15437
23877
2.15437
23813
2.15436
23414
2.15435
23372
2.15435
23434
2.15434
23343
2.15433
23071
2.15433
23148
2.15432
23141
2.15431
23008
2.15431
22967
2.1543
22936
2.1543
23012
2.15429
23240
2.15428
23176
2.15428
23274
2.15427
23584
2.15426
23512
2.15426
23542
2.15425
23560
2.15424
23570
2.15424
23712
2.15423
23399
2.15422
23343
2.15422
23277
2.15421
23048
2.1542
22861
2.1542
23075
2.15419
22903
2.15418
22990
2.15418
23156
2.15417
23426
2.15416
23288
2.15416
23073
2.15415
22862
2.15414
23128
2.15414
23282
2.15413
23217
2.15412
22929
2.15412
23156
2.15411
23184
2.1541
23092
2.1541
23221
2.15409
23150
2.15408
23121
2.15408
22819
2.15407
22886
2.15406
22801
2.15406
23186
2.15405
Mo 3d
RW_Nb_MoS2
2020
9
3
21
7
57
2
59
Casa Info Follows
2
Calib M = 281.0399 A = 285.09 BE ADD
Calib M = 285.0903 A = 284.8 BE ADD
0
1
CASA region (*Mo 3d*) (*Shirley*) 1249.3343 1262.7065 10.804667 2 0 0 392.54541 -450 0 0 (*Mo 3d*) 95.9219 0 9.5
10
CASA comp (*Mo 3d MoS2 2H*) (*LA(1.53,243)*) Area 402.58291 1e-020 2327991 -1 1 MFWHM 0.54805002 0.2 2 -1 1 Position 1257.22 1257.02 1257.22 -1 1 RSF 10.804667 MASS 95.9219 INDEX -1 (*Mo 3d*) CONST (**) UNCORRECTEDRSF 9.5
CASA comp (*Mo 3d MoS2 2H*) (*LA(1.53,243)*) Area 268.38861 1e-020 2327991 0 0.66666667 MFWHM 0.65389948 0.65389948 1.2538995 -1 1 Position 1254.08 0 0 0 -3.14 RSF 10.804667 MASS 95.9219 INDEX -1 (*Mo 3d*) CONST (**) UNCORRECTEDRSF 9.5
CASA comp (*Mo 3d MoS2 1T*) (*LA(1.53,243)*) Area 23557.769 1e-020 2327991 -1 1 MFWHM 1.2344544 0.2533 1.5 -1 1 Position 1258.0814 1257.89 1258.49 -1 1 RSF 10.804667 MASS 95.9219 INDEX -1 (*Mo 3d*) CONST (**) UNCORRECTEDRSF 9.5
CASA comp (*Mo 3d MoS2 1T*) (*LA(1.53,243)*) Area 15705.18 1e-020 2327991 2 0.66666667 MFWHM 1.2344544 0.2532592 6.33148 2 1 Position 1254.9414 0 0 2 -3.14 RSF 10.804667 MASS 95.9219 INDEX -1 (*Mo 3d*) CONST (**) UNCORRECTEDRSF 9.5
CASA comp (*Mo 3d MoO3*) (*LA(1.53,243)*) Area 1101.0127 1e-020 1384876 -1 1 MFWHM 0.8022371 0.285 2 -1 1 Position 1253.99 1253.39 1253.99 -1 1 RSF 10.804667 MASS 95.9219 INDEX -1 (*Mo 3d*) CONST (**) UNCORRECTEDRSF 9.5
CASA comp (*S 2s*) (*LA(1.53,243)*) Area 5395.1758 1e-020 2327991 -1 1 MFWHM 1.5399213 0.20524482 5.1311205 -1 1 Position 1260.9011 1258.0143 1262.0143 -1 1 RSF 10.804667 MASS 95.9219 INDEX -1 (*Mo 3d*) CONST (**) UNCORRECTEDRSF 9.5
CASA comp (*Mo 3d MoO2*) (*LA(1.53,243)*) Area 298.93846 1e-020 2327991 -1 1 MFWHM 0.6968721 0.2949 2 -1 1 Position 1255.8573 1255.8573 1256.4573 -1 1 RSF 10.804667 MASS 95.9219 INDEX -1 (*Mo 3d*) CONST (**) UNCORRECTEDRSF 9.5
CASA comp (*Mo 3d MoO2*) (*LA(1.53,243)*) Area 199.29231 1e-020 2327991 6 0.66666667 MFWHM 0.6968721 0.2949286 7.3732149 6 1 Position 1252.7173 0 0 6 -3.14 RSF 10.804667 MASS 95.9219 INDEX -1 (*Mo 3d*) CONST (**) UNCORRECTEDRSF 9.5
CASA comp (*Mo 3d MoO3*) (*LA(1.53,243)*) Area 8166.4944 1e-020 2327991 -1 1 MFWHM 1.7530761 0.2537 2 -1 1 Position 1254.376 1253.615 1254.69 -1 1 RSF 10.804667 MASS 95.9219 INDEX -1 (*Mo 3d*) CONST (**) UNCORRECTEDRSF 9.5
CASA comp (*Mo 3d MoO3*) (*LA(1.53,243)*) Area 5444.3296 1e-020 2327991 8 0.66666667 MFWHM 1.7530761 0.25368427 6.3421067 8 1 Position 1251.236 0 0 8 -3.14 RSF 10.804667 MASS 95.9219 INDEX -1 (*Mo 3d*) CONST (**) UNCORRECTEDRSF 9.5
Creation
Created by : DESKTOP-MI6NA2R\kratos
Date created : 03/09/2020 21:07
Computer : DESKTOP-MI6NA2R
Location
Location ID : RW_Nb_MoS2
Sample : RW_Nb_MoS2
Description : (32.368,22.987,-1.908)mm
Tilt : 0.00
Charge Neutraliser : On
Filament Current : 0.45A
Filament Bias : 1V
Charge Balance : 4.9V
Settings
Excitation
Mode : XPS - monochromatic
Tuning : Spectroscopy
Emission current : 15.00mA
Anode library : Al
ESCA modes
Collimation : Slot
Lens : Hybrid
Resolution : 40.00
Scan
Deflection : (0.000, 0.000)mm
Mo 3d : 1246.715-1266.665eV, Sweeps 6
Start : 1246.715eV
End : 1266.665eV
Centre : 1256.690eV
Width : 19.950eV
Step size : 0.150eV
Number Steps : 133
Dwell time : 448ms
Sweep time : 60s
Sweeps : 6
Target quality : 300
Instrument Conditions
Work function : -4.50
Acquisition Conditions
X-ray Power : 225.00W
Quality : 154.37
XPS
63
32.368
22.9871
-1.90798
Al (mono)
1486.69
225
1e+037
1e+037
1e+037
1e+037
FAT
40
1e+037
-4.5
1e+037
1e+037
1e+037
1e+037
1e+037
Mo
3d
-1
Kinetic energy
eV
1246.715
0.15
2
Intensity
d
Transmission
d
pulse counting
0.44776
6
0
1e+037
1e+037
1e+037
3
ESCAPE DEPTH TYPE
d
1
MFP Exponent
d
0
PROPAGATION_CONVERGED
d
1
268
30298
76974
2.15515
2.15603
37000
2.15603
37555
2.15602
37381
2.15601
37404
2.15601
37096
2.156
36703
2.15599
37033
2.15599
36778
2.15598
36904
2.15597
36798
2.15597
36433
2.15596
36542
2.15596
36475
2.15595
36507
2.15594
36532
2.15594
36217
2.15593
36068
2.15592
35883
2.15592
36340
2.15591
36127
2.1559
36157
2.1559
36063
2.15589
35729
2.15588
35782
2.15588
36268
2.15587
36114
2.15586
36149
2.15586
35882
2.15585
35993
2.15584
36011
2.15584
35839
2.15583
35701
2.15582
36009
2.15582
35912
2.15581
35852
2.1558
35890
2.1558
36048
2.15579
36101
2.15578
36043
2.15578
36056
2.15577
35966
2.15576
36169
2.15576
35793
2.15575
36063
2.15574
36486
2.15574
36581
2.15573
36998
2.15572
37655
2.15572
38418
2.15571
39312
2.1557
40411
2.1557
41401
2.15569
42220
2.15568
42988
2.15568
43503
2.15567
43972
2.15566
43619
2.15566
43410
2.15565
42924
2.15565
42246
2.15564
41354
2.15563
40725
2.15563
40289
2.15562
39612
2.15561
39391
2.15561
38999
2.1556
38918
2.15559
39565
2.15559
40422
2.15558
41556
2.15557
43318
2.15557
45881
2.15556
49226
2.15555
53072
2.15555
57450
2.15554
62085
2.15553
66123
2.15553
69790
2.15552
71612
2.15551
72524
2.15551
72151
2.1555
69293
2.15549
65698
2.15549
60981
2.15548
54708
2.15547
48742
2.15547
43469
2.15546
39625
2.15545
37247
2.15545
35835
2.15544
35127
2.15543
34918
2.15543
35733
2.15542
38232
2.15541
41535
2.15541
46979
2.1554
54008
2.15539
61752
2.15539
68428
2.15538
73153
2.15537
76146
2.15537
76974
2.15536
75253
2.15535
72123
2.15535
65586
2.15534
56175
2.15534
46848
2.15533
39612
2.15532
35713
2.15532
34002
2.15531
33881
2.1553
34291
2.1553
34668
2.15529
35398
2.15528
36396
2.15528
37328
2.15527
37929
2.15526
38417
2.15526
39114
2.15525
39733
2.15524
39513
2.15524
39090
2.15523
38402
2.15522
37487
2.15522
36557
2.15521
35538
2.1552
34432
2.1552
33203
2.15519
32634
2.15518
31878
2.15518
31566
2.15517
30871
2.15516
30594
2.15516
30298
2.15515
W 4f
RW_Nb_MoS2
2020
9
3
21
7
57
2
48
Casa Info Follows
2
Calib M = 281.0399 A = 285.09 BE ADD
Calib M = 285.0903 A = 284.8 BE ADD
0
0
0
Creation
Created by : DESKTOP-MI6NA2R\kratos
Date created : 03/09/2020 21:07
Computer : DESKTOP-MI6NA2R
Location
Location ID : RW_Nb_MoS2
Sample : RW_Nb_MoS2
Description : (32.368,22.987,-1.908)mm
Tilt : 0.00
Charge Neutraliser : On
Filament Current : 0.45A
Filament Bias : 1V
Charge Balance : 4.9V
Settings
Excitation
Mode : XPS - monochromatic
Tuning : Spectroscopy
Emission current : 15.00mA
Anode library : Al
ESCA modes
Collimation : Slot
Lens : Hybrid
Resolution : 40.00
Scan
Deflection : (0.000, 0.000)mm
W 4f : 1441.715-1461.665eV, Sweeps 6
Start : 1441.715eV
End : 1461.665eV
Centre : 1451.690eV
Width : 19.950eV
Step size : 0.150eV
Number Steps : 133
Dwell time : 448ms
Sweep time : 60s
Sweeps : 6
Target quality : 200
Instrument Conditions
Work function : -4.50
Acquisition Conditions
X-ray Power : 225.00W
Quality : 142.05
XPS
64
32.368
22.9871
-1.90798
Al (mono)
1486.69
225
1e+037
1e+037
1e+037
1e+037
FAT
40
1e+037
-4.5
1e+037
1e+037
1e+037
1e+037
1e+037
W
4f
-1
Kinetic energy
eV
1441.715
0.15
2
Intensity
d
Transmission
d
pulse counting
0.44776
6
0
1e+037
1e+037
1e+037
3
ESCAPE DEPTH TYPE
d
1
MFP Exponent
d
0
PROPAGATION_CONVERGED
d
1
268
4217
12831
2.15606
2.16581
12831
2.15606
12655
2.15613
12605
2.1562
12775
2.15628
12805
2.15635
12700
2.15642
12631
2.1565
12598
2.15657
12772
2.15664
12629
2.15672
12581
2.15679
12571
2.15686
12505
2.15694
12564
2.15701
12368
2.15708
12182
2.15716
12169
2.15723
12331
2.1573
12163
2.15738
12005
2.15745
11985
2.15752
11989
2.1576
11873
2.15767
11780
2.15774
11724
2.15782
11680
2.15789
11559
2.15796
11435
2.15804
11422
2.15811
11327
2.15818
11123
2.15826
11233
2.15833
11031
2.1584
11044
2.15848
10777
2.15855
10801
2.15862
10848
2.1587
10737
2.15877
10709
2.15884
10600
2.15892
10442
2.15899
10474
2.15906
10530
2.15914
10540
2.15921
10130
2.15928
10274
2.15936
10360
2.15943
10315
2.1595
10293
2.15958
10233
2.15965
10187
2.15972
10202
2.1598
10145
2.15987
10073
2.15994
10208
2.16002
10238
2.16009
10173
2.16016
10372
2.16024
10283
2.16031
10254
2.16038
10241
2.16046
10187
2.16053
10248
2.1606
9993
2.16068
10112
2.16075
9973
2.16082
9989
2.16089
9891
2.16097
9811
2.16104
9663
2.16111
9592
2.16119
9400
2.16126
9413
2.16133
9498
2.16141
9372
2.16148
9215
2.16155
9203
2.16163
9044
2.1617
9097
2.16177
9124
2.16185
9128
2.16192
9014
2.16199
9067
2.16207
9087
2.16214
8913
2.16221
8777
2.16229
8443
2.16236
8334
2.16243
8004
2.16251
7687
2.16258
7247
2.16265
6970
2.16273
6644
2.1628
6224
2.16287
6054
2.16295
5736
2.16302
5574
2.16309
5438
2.16317
5454
2.16324
5255
2.16331
5058
2.16339
4988
2.16346
4871
2.16353
4882
2.16361
4775
2.16368
4716
2.16375
4694
2.16383
4645
2.1639
4576
2.16397
4529
2.16405
4512
2.16412
4486
2.16419
4473
2.16427
4374
2.16434
4368
2.16441
4319
2.16449
4217
2.16456
4257
2.16463
4304
2.16471
4315
2.16478
4296
2.16485
4384
2.16493
4448
2.165
4560
2.16507
4595
2.16515
4812
2.16522
5036
2.16529
5258
2.16537
5719
2.16544
6137
2.16551
6727
2.16559
7511
2.16566
8524
2.16573
10085
2.16581
1: S 2p
RW_Nb_MoS2
2020
9
3
22
32
4
2
53
Casa Info Follows
2
Calib M = 281.0399 A = 285.09 BE ADD
Calib M = 285.0903 A = 284.8 BE ADD
0
1
CASA region (*S 2p*) (*U 2 Tougaard*) 1320.746 1327.3909 0.66800007 2 0 0 2372.417 -450 0 0 (*S 2p*) 32.0648 0 0.668
4
CASA comp (*S 2p WS2*) (*GL(30)*) Area 1e-020 1e-020 291645.06 -1 1 MFWHM 1 0.5 1 -1 1 Position 1323.9377 1323.9177 1324.1177 -1 1 RSF 0.66800007 MASS 32.0648 INDEX -1 (*S 2p*) CONST (**) UNCORRECTEDRSF 0.668
CASA comp (*S 2p WS2*) (*GL(30)*) Area 5e-021 1e-020 291645.06 0 0.5 MFWHM 1 0.2 5 0 1 Position 1322.7777 0 0 0 -1.16 RSF 0.66800007 MASS 32.0648 INDEX -1 (*S 2p*) CONST (**) UNCORRECTEDRSF 0.668
CASA comp (*S 2p MoS2*) (*GL(30)*) Area 10898.581 1e-020 291645.06 -1 1 MFWHM 1.4196213 0.2 5 -1 1 Position 1325.1223 1324.7223 1325.1223 -1 1 RSF 0.66800007 MASS 32.0648 INDEX -1 (*S 2p*) CONST (**) UNCORRECTEDRSF 0.668
CASA comp (*S 2p MoS2*) (*GL(30)*) Area 5449.2906 1e-020 291645.06 2 0.5 MFWHM 1.4196213 0.2 5 2 1 Position 1323.9623 0 0 2 -1.16 RSF 0.66800007 MASS 32.0648 INDEX -1 (*S 2p*) CONST (**) UNCORRECTEDRSF 0.668
Creation
Created by : DESKTOP-MI6NA2R\kratos
Date created : 03/09/2020 22:32
Computer : DESKTOP-MI6NA2R
Location
Location ID : RW_Nb_MoS2
Sample : RW_Nb_MoS2
Description : (32.368,22.987,-1.908)mm
Tilt : 0.00
Charge Neutraliser : On
Filament Current : 0.45A
Filament Bias : 1V
Charge Balance : 4.9V
Settings
Excitation
Mode : XPS - monochromatic
Tuning : Spectroscopy
Emission current : 15.00mA
Anode library : Al
ESCA modes
Collimation : Slot
Lens : Hybrid
Resolution : 40.00
Scan
Deflection : (0.000, 0.000)mm
S 2p : 1314.715-1334.665eV, Sweeps 5
Start : 1314.715eV
End : 1334.665eV
Centre : 1324.690eV
Width : 19.950eV
Step size : 0.150eV
Number Steps : 133
Dwell time : 448ms
Sweep time : 60s
Sweeps : 5
Target quality : 300
Instrument Conditions
Work function : -4.50
Acquisition Conditions
X-ray Power : 225.00W
Quality : 143.12
XPS
65
32.368
22.9871
-1.90798
Al (mono)
1486.69
225
1e+037
1e+037
1e+037
1e+037
FAT
40
1e+037
-4.5
1e+037
1e+037
1e+037
1e+037
1e+037
S
2p
-1
Kinetic energy
eV
1314.715
0.15
2
Intensity
d
Transmission
d
pulse counting
0.447761
5
0
1e+037
1e+037
1e+037
3
ESCAPE DEPTH TYPE
d
1
MFP Exponent
d
0
PROPAGATION_CONVERGED
d
1
268
19511
36857
2.12923
2.1433
21960
2.1433
21719
2.1432
21625
2.14309
21580
2.14299
21727
2.14288
21584
2.14277
21603
2.14267
21548
2.14256
21825
2.14246
21745
2.14235
21672
2.14225
21765
2.14214
21575
2.14203
21486
2.14193
21794
2.14182
21664
2.14172
21771
2.14161
21706
2.14151
21666
2.1414
21706
2.14129
21807
2.14119
21887
2.14108
21975
2.14098
22078
2.14087
22017
2.14076
21799
2.14066
21787
2.14055
21911
2.14045
21992
2.14034
21883
2.14024
21779
2.14013
21811
2.14002
21793
2.13992
21889
2.13981
21884
2.13971
21965
2.1396
22153
2.13949
22162
2.13939
22108
2.13928
22392
2.13918
22490
2.13907
22781
2.13897
22621
2.13886
22596
2.13875
22794
2.13865
23063
2.13854
23062
2.13844
23178
2.13833
23038
2.13822
23225
2.13812
23002
2.13801
23030
2.13791
22664
2.1378
22353
2.1377
22187
2.13759
21930
2.13748
21601
2.13738
21577
2.13727
21463
2.13717
21470
2.13706
21498
2.13696
21609
2.13685
21659
2.13674
21443
2.13664
21548
2.13653
21530
2.13643
21425
2.13632
21587
2.13621
21526
2.13611
21619
2.136
21694
2.1359
21501
2.13579
21500
2.13569
21623
2.13558
21235
2.13547
21424
2.13537
21546
2.13526
21592
2.13516
21942
2.13505
22194
2.13494
22566
2.13484
23123
2.13473
24329
2.13463
25412
2.13452
26865
2.13442
28119
2.13431
28965
2.1342
29954
2.1341
31025
2.13399
32617
2.13389
33836
2.13378
34870
2.13367
35902
2.13357
36059
2.13346
36565
2.13336
36857
2.13325
36432
2.13315
35572
2.13304
34129
2.13293
31250
2.13283
27331
2.13272
24616
2.13262
22361
2.13251
21022
2.13241
20394
2.1323
20219
2.13219
19962
2.13209
19857
2.13198
19811
2.13188
19998
2.13177
19938
2.13166
19899
2.13156
20117
2.13145
19891
2.13135
19511
2.13124
19641
2.13114
19692
2.13103
19756
2.13092
19528
2.13082
19540
2.13071
19695
2.13061
19745
2.1305
19603
2.13039
19740
2.13029
19770
2.13018
19633
2.13008
19625
2.12997
19793
2.12987
19581
2.12976
19737
2.12965
19761
2.12955
19661
2.12944
19835
2.12934
19818
2.12923
1: N 1s
RW_Nb_MoS2
2020
9
4
15
3
21
2
48
Casa Info Follows
2
Calib M = 281.0399 A = 285.09 BE ADD
Calib M = 285.0903 A = 284.8 BE ADD
0
0
0
Creation
Created by : DESKTOP-MI6NA2R\kratos
Date created : 04/09/2020 15:03
Computer : DESKTOP-MI6NA2R
Location
Location ID : RW_Nb_MoS2
Sample : RW_Nb_MoS2
Description : (32.368,22.987,-1.908)mm
Tilt : 0.00
Charge Neutraliser : On
Filament Current : 0.45A
Filament Bias : 1V
Charge Balance : 4.9V
Settings
Excitation
Mode : XPS - monochromatic
Tuning : Spectroscopy
Emission current : 15.00mA
Anode library : Al
ESCA modes
Collimation : Slot
Lens : Hybrid
Resolution : 40.00
Scan
Deflection : (0.000, 0.000)mm
N 1s : 1071.690-1101.690eV, Sweeps 5
Start : 1071.690eV
End : 1101.690eV
Centre : 1086.690eV
Width : 30.000eV
Step size : 0.150eV
Number Steps : 200
Dwell time : 299ms
Sweep time : 60s
Sweeps : 5
Target quality : 300
Instrument Conditions
Work function : -4.50
Acquisition Conditions
X-ray Power : 225.00W
Quality : 128.88
XPS
66
32.368
22.9871
-1.90798
Al (mono)
1486.69
225
1e+037
1e+037
1e+037
1e+037
FAT
40
1e+037
-4.5
1e+037
1e+037
1e+037
1e+037
1e+037
N
1s
-1
Kinetic energy
eV
1071.69
0.15
2
Intensity
d
Transmission
d
pulse counting
0.298507
5
0
1e+037
1e+037
1e+037
0
402
19844
33476
2.1702
2.17351
24709
2.1702
25018
2.17022
24867
2.17023
24684
2.17025
24821
2.17027
25111
2.17029
25198
2.1703
25299
2.17032
25273
2.17034
25199
2.17036
25306
2.17038
25580
2.17039
25403
2.17041
25759
2.17043
25622
2.17045
25787
2.17046
25796
2.17048
26055
2.1705
26023
2.17052
26162
2.17053
26100
2.17055
25845
2.17057
26001
2.17059
26275
2.1706
26251
2.17062
26057
2.17064
26141
2.17066
26086
2.17067
25966
2.17069
25998
2.17071
26136
2.17073
25971
2.17075
26028
2.17076
26251
2.17078
26132
2.1708
26251
2.17082
26353
2.17083
26685
2.17085
26943
2.17087
26956
2.17089
27196
2.1709
27774
2.17092
27910
2.17094
27987
2.17096
28086
2.17097
28233
2.17099
28167
2.17101
28023
2.17103
27838
2.17104
27605
2.17106
26950
2.17108
26524
2.1711
25895
2.17112
25442
2.17113
24981
2.17115
24673
2.17117
24577
2.17119
24230
2.1712
23775
2.17122
23611
2.17124
23538
2.17126
23306
2.17127
23007
2.17129
22834
2.17131
22701
2.17133
22846
2.17134
22896
2.17136
22645
2.17138
22665
2.1714
22599
2.17142
22557
2.17143
22232
2.17145
21889
2.17147
22195
2.17149
22285
2.1715
22162
2.17152
22261
2.17154
22241
2.17156
22106
2.17157
22330
2.17159
22033
2.17161
21776
2.17163
22034
2.17164
21827
2.17166
21894
2.17168
21847
2.1717
21856
2.17171
21975
2.17173
21997
2.17175
22062
2.17177
21932
2.17179
21886
2.1718
21905
2.17182
21871
2.17184
21898
2.17186
22126
2.17187
21706
2.17189
21748
2.17191
21775
2.17193
21876
2.17194
22062
2.17196
22019
2.17198
21872
2.172
21797
2.17201
21860
2.17203
22083
2.17205
22049
2.17207
22173
2.17208
22417
2.1721
22400
2.17212
22533
2.17214
22732
2.17216
23036
2.17217
23201
2.17219
23749
2.17221
24327
2.17223
24880
2.17224
25317
2.17226
26644
2.17228
27474
2.1723
28439
2.17231
30025
2.17233
31410
2.17235
32494
2.17237
33075
2.17238
33476
2.1724
33229
2.17242
32886
2.17244
31916
2.17246
31260
2.17247
30084
2.17249
28928
2.17251
28041
2.17253
27390
2.17254
26789
2.17256
26414
2.17258
25881
2.1726
25911
2.17261
25823
2.17263
25520
2.17265
25431
2.17267
25442
2.17268
25357
2.1727
25157
2.17272
25038
2.17274
24994
2.17275
24945
2.17277
24986
2.17279
24877
2.17281
25070
2.17283
25356
2.17284
25407
2.17286
25587
2.17288
25906
2.1729
26457
2.17291
27277
2.17293
27486
2.17295
28050
2.17297
28521
2.17298
29407
2.173
29558
2.17302
29545
2.17304
29717
2.17305
29899
2.17307
29432
2.17309
28838
2.17311
28048
2.17312
27738
2.17314
27144
2.17316
26238
2.17318
25377
2.1732
24442
2.17321
23940
2.17323
23347
2.17325
23169
2.17327
22837
2.17328
22362
2.1733
21892
2.17332
21646
2.17334
21533
2.17335
21162
2.17337
21164
2.17339
21184
2.17341
21009
2.17342
20746
2.17344
20671
2.17346
20764
2.17348
20641
2.1735
20630
2.17351
20300
2.17351
20143
2.17347
20256
2.17343
20444
2.17338
20182
2.17334
20139
2.17329
20109
2.17325
19932
2.17321
20019
2.17316
20022
2.17312
19927
2.17308
19844
2.17303
end of experiment