File: src/parser/__tests__/data/polyethyleneglycol.vms
VAMAS Surface Chemical Analysis Standard Data Transfer Format 1988 May 4
SurfaceSpectra Ltd.
Scienta ESCA300
G Beamson
Poly(ethylene glycol)
6
Casa Info Follows CasaXPS Version 2.3.22PR1.0
0
The XPS of Polymers Database
Copyright (c) 2000 SurfaceSpectra Ltd.
SourceAnalyserAngle: 54.735600 d
CasaRowLabel:Sample Name: Poly(ethylene glycol)
NORM
REGULAR
4
1
None
d
0
0
0
0
4
Survey
Sample Name: Poly(ethylene glycol)
2000
3
1
1
0
0
0
8
Casa Info Follows
0
0
0
0
Sample Name: Poly(ethylene glycol)
The XPS of Polymers Database
Copyright (c) 2000 SurfaceSpectra Ltd.
XPS
0
Al Ka, Monochromated
1486.6
1400
6000
500
45
315
FAT
300
5
1e+037
0
6000
500
45
0
Survey

-1
Binding energy
eV
1152.2
-1
1
Counts
d
pulse counting
0.1
3
1e+037
90
0
0
0
1151
20
9179
1197
1218
1223
1178
1260
1251
1288
1337
1216
1253
1202
1284
1239
1229
1317
1193
1277
1219
1340
1187
1191
1330
1256
1302
1248
1289
1287
1229
1252
1370
1366
1364
1321
1257
1271
1225
1396
1306
1391
1306
1363
1369
1355
1325
1305
1325
1322
1448
1333
1289
1323
1398
1329
1379
1349
1370
1378
1391
1410
1356
1298
1356
1418
1354
1406
1316
1314
1341
1467
1410
1340
1365
1397
1357
1377
1398
1438
1404
1416
1456
1428
1521
1540
1388
1375
1446
1352
1401
1423
1386
1389
1461
1395
1436
1430
1472
1413
1460
1485
1462
1519
1385
1437
1464
1502
1408
1468
1523
1482
1590
1543
1587
1599
1514
1546
1477
1496
1519
1535
1475
1533
1573
1519
1557
1468
1484
1487
1522
1512
1555
1583
1637
1740
1584
1679
1741
1705
1612
1594
1569
1567
1514
1566
1595
1614
1608
1613
1662
1690
1684
1764
1802
1831
1887
1818
1711
1685
1735
1839
1769
1603
1672
1746
1631
1449
1538
1504
1526
1511
1582
1593
1772
1850
1902
1956
2121
2100
2082
1889
1776
1594
1582
1462
1412
1274
1154
1050
966
886
929
879
886
874
908
901
858
829
822
829
881
854
868
805
863
853
920
882
857
857
849
867
906
878
875
863
854
877
958
945
917
847
913
912
918
899
903
949
851
909
939
919
926
877
854
907
954
885
870
967
870
870
953
911
867
866
856
936
892
877
848
899
862
868
957
898
925
900
840
950
932
918
910
928
914
909
918
868
942
910
910
880
913
886
950
905
874
971
948
973
961
872
909
837
849
936
978
912
851
933
849
892
964
890
871
953
889
966
908
984
959
919
975
930
984
968
966
914
915
938
914
972
881
1009
942
953
968
975
981
987
1000
962
969
949
959
1004
1004
978
993
961
996
1015
969
1006
1033
929
922
1010
993
946
981
1003
943
1006
996
991
980
932
1004
924
985
927
980
1037
1014
941
992
990
1004
976
981
1013
1019
1037
1055
990
1026
960
936
989
1000
989
989
1025
1027
985
966
1056
1061
1068
1080
990
1093
1008
992
995
1036
1055
1059
1005
1006
1057
1040
1057
1021
1062
1060
1128
1109
1026
962
1014
1075
992
1107
1079
968
1049
1089
1104
981
1050
1104
1007
1017
1078
1032
1116
1105
1052
1084
1032
1075
1069
1081
1105
1049
1028
1084
1037
1087
1057
1102
1065
1067
1093
1113
1057
1124
1072
1176
1098
1039
1076
1085
1121
1052
1060
1119
1089
1069
1019
1015
1089
1058
1137
1016
1083
1047
1198
1071
1108
1121
1077
1086
1135
1190
1106
1147
1104
1134
1109
1138
1081
1055
1115
1153
1099
1107
1116
1074
1068
1194
1149
1109
1063
1141
1087
1090
1084
1154
1056
1149
1128
1092
1098
1146
1090
1186
1102
1031
1119
1142
1106
1115
1104
1211
1132
1161
1127
1061
1087
1149
1156
1162
1151
1190
1120
1161
1135
1133
1104
1180
1136
1184
1173
1233
1163
1149
1118
1149
1139
1215
1192
1076
1129
1234
1234
1144
1217
1262
1106
1212
1231
1131
1146
1177
1170
1175
1187
1140
1186
1170
1211
1111
1183
1169
1191
1196
1155
1189
1168
1172
1227
1317
1232
1168
1105
1219
1096
1142
1138
1154
1194
1186
1212
1235
1257
1148
1225
1185
1257
1168
1146
1129
1129
1183
1122
1053
1167
1171
1047
1209
1124
1246
1256
1263
1269
1251
1317
1378
1302
1288
1226
1196
1188
1149
944
929
875
817
799
718
703
643
612
567
598
644
564
814
3382
9179
3721
747
562
533
561
564
536
498
502
495
532
496
502
512
468
537
504
464
518
478
480
552
531
542
461
495
518
532
509
453
491
462
487
568
526
545
534
521
502
477
483
523
504
546
496
501
538
479
534
493
519
495
573
500
539
539
547
506
479
485
491
478
533
540
512
573
490
495
474
510
501
486
510
538
482
494
491
500
527
514
439
509
509
489
569
475
457
514
498
515
492
516
463
529
491
525
501
495
461
509
527
558
471
518
526
498
529
532
542
514
540
499
505
487
552
552
523
541
508
522
518
513
507
552
503
538
482
534
554
557
560
526
569
561
544
582
503
516
530
547
530
532
540
534
530
524
535
594
553
520
571
593
505
562
535
499
585
549
503
546
544
522
512
549
563
534
557
517
566
517
613
574
581
553
560
556
521
570
608
559
526
515
569
491
585
566
546
541
579
516
587
529
544
575
578
576
581
557
584
594
586
576
606
579
570
526
571
585
598
570
559
551
519
602
499
594
538
532
580
563
644
629
639
664
629
659
562
609
555
518
494
404
364
357
303
281
261
206
129
126
118
115
141
188
1092
5754
3783
333
130
81
74
65
75
70
67
72
57
62
77
65
51
64
84
62
43
54
59
61
55
63
55
69
59
67
49
42
62
73
65
46
37
55
57
55
56
53
61
47
47
63
62
62
63
68
45
61
53
57
51
48
38
64
61
51
62
50
54
55
57
68
57
56
54
78
80
53
63
48
70
54
48
40
45
60
55
56
46
50
37
49
55
68
67
54
61
57
51
65
63
64
54
57
44
55
50
39
66
42
46
61
59
51
59
69
54
47
61
46
55
52
63
61
54
78
67
53
51
61
39
75
61
63
56
61
53
62
52
67
49
48
54
61
63
63
48
52
53
52
64
54
61
60
54
61
48
65
68
54
31
61
74
56
64
70
79
64
61
42
64
58
73
66
57
69
60
55
48
47
50
67
63
51
48
64
52
55
79
45
63
65
71
53
71
56
65
61
59
50
85
58
49
65
79
70
56
51
54
50
58
59
58
57
62
76
77
49
62
52
61
53
41
42
73
52
61
69
47
61
58
52
50
49
55
62
49
69
66
66
67
67
60
77
62
64
78
71
75
47
45
61
79
73
52
62
55
69
55
33
47
55
34
62
47
79
120
174
159
87
54
39
23
28
69
83
82
71
70
104
72
20
27
46
34
23
37
44
36
37
26
C 1s
Sample Name: Poly(ethylene glycol)
2000
3
1
1
0
0
0
9
Casa Info Follows
0
0
1
CASA region (*C 1s*) (*Shirley*) 1194.8785 1203.5916 0.278 2 0 0 115.3918 -450 0 0 (*C 1s*) 12.011 0 0.278
0
Sample Name: Poly(ethylene glycol)
The XPS of Polymers Database
Copyright (c) 2000 SurfaceSpectra Ltd.
XPS
0
Al Ka, Monochromated
1486.6
1400
6000
500
45
315
FAT
150
5
1e+037
0
6000
500
45
0
C
1s
-1
Binding energy
eV
293.2
-0.05
1
Counts
d
pulse counting
0.1
25
1e+037
90
0
0
0
240
115
16344
229
242
217
223
211
226
221
217
203
205
223
207
182
183
197
184
187
196
182
174
183
199
191
181
191
189
168
181
175
181
190
192
183
165
181
188
189
198
185
185
196
196
201
205
206
216
210
215
202
219
181
215
203
200
213
195
222
250
244
223
230
226
231
254
213
248
240
244
265
265
294
311
289
262
276
285
300
307
290
281
278
293
301
320
288
318
317
345
350
357
395
348
379
409
407
479
467
490
545
583
643
748
741
814
915
1026
1155
1280
1470
1620
1867
2089
2405
2788
3199
3561
4060
4616
5345
5932
6729
7458
8265
9036
9790
10767
11721
12599
13451
14276
14839
15613
16031
16344
16228
16140
15798
15364
14711
13421
12146
10880
9480
8167
6936
5916
4952
3958
3135
2535
2051
1659
1450
1219
1051
955
843
751
778
695
654
619
636
601
554
483
484
486
445
437
416
392
357
341
326
290
286
266
241
248
235
220
209
187
195
199
210
210
192
193
173
178
180
173
174
177
167
165
159
156
170
146
153
154
139
154
163
148
151
149
142
129
147
147
147
143
129
144
138
135
142
157
157
142
130
127
120
125
132
150
154
132
140
129
132
122
115
128
119
131
O 1s
Sample Name: Poly(ethylene glycol)
2000
3
1
1
0
0
0
9
Casa Info Follows
0
0
1
CASA region (*O 1s*) (*Shirley*) 948.94979 957.88387 0.78 2 0 0 115.3918 -450 0 0 (*O 1s*) 15.9994 0 0.78
0
Sample Name: Poly(ethylene glycol)
The XPS of Polymers Database
Copyright (c) 2000 SurfaceSpectra Ltd.
XPS
0
Al Ka, Monochromated
1486.6
1400
6000
500
45
315
FAT
150
5
1e+037
0
6000
500
45
0
O
1s
-1
Binding energy
eV
538.2
-0.05
1
Counts
d
pulse counting
0.1
25
1e+037
90
0
0
0
200
894
21726
1020
965
985
988
1029
1057
1015
1018
1009
1019
1005
1012
1009
1040
1031
992
1051
1034
1009
1033
1041
1041
1066
1100
1090
1082
1062
1092
1090
1034
1058
1041
1045
1060
1033
1036
1088
1085
1031
1050
1083
1116
1135
1096
1086
1114
1148
1066
1079
1096
1137
1129
1111
1147
1136
1145
1153
1213
1209
1180
1214
1262
1226
1230
1265
1291
1356
1390
1403
1434
1516
1534
1540
1662
1777
1916
2001
2110
2350
2586
2776
2985
3322
3684
4070
4532
4960
5626
6285
7034
7880
8771
9785
10688
11738
12941
13968
15140
16067
17118
18147
19007
19812
20716
21032
21335
21726
21446
21034
20493
19920
19070
17899
16737
15764
14529
13061
11644
10422
9148
7942
7061
6055
5271
4568
3937
3467
2968
2675
2469
2219
1986
1858
1731
1609
1614
1564
1487
1398
1349
1386
1359
1309
1263
1252
1227
1213
1188
1160
1182
1178
1112
1154
1070
1069
1082
1102
1099
1047
1056
1037
1025
1052
1007
1032
1034
990
1045
1009
1000
1040
987
1021
985
988
1012
1009
1007
979
995
990
964
980
976
987
960
910
932
958
948
928
956
973
958
944
919
940
969
909
894
Valence
Sample Name: Poly(ethylene glycol)
2000
3
1
1
0
0
0
8
Casa Info Follows
0
0
0
0
Sample Name: Poly(ethylene glycol)
The XPS of Polymers Database
Copyright (c) 2000 SurfaceSpectra Ltd.
XPS
0
Al Ka, Monochromated
1486.6
2800
6000
500
45
315
FAT
150
5
1e+037
0
6000
500
45
0
Valence

-1
Binding energy
eV
38.42
-0.05
1
Counts
d
pulse counting
1
10
1e+037
90
0
0
0
801
34
16214
5214
5340
5318
5250
5196
5211
5310
5205
5271
5252
5299
5205
5163
5267
5181
5147
5136
5106
5113
5176
5109
5102
5128
5123
5175
5115
5133
4957
4974
5082
5166
5142
5007
5088
5191
4996
4918
5113
5077
5021
4984
4969
5049
5073
4991
4948
4948
4949
5065
5003
4922
4977
5025
5035
4930
4940
4849
4814
4865
4966
4920
4884
4857
4892
4995
4936
4992
4999
4798
4831
4902
4852
4772
4938
4881
4883
4787
4759
4835
4864
4839
4884
4835
4865
4842
4868
4873
4887
4752
4750
4733
4928
4929
4885
4890
4837
4789
4797
4708
4837
4869
4849
4778
4824
4843
4712
4702
4760
4726
4812
4836
4750
4825
4876
4927
4914
4896
4822
4826
4881
4828
4889
4899
4841
4839
4893
4798
4864
4964
5017
5031
4987
4971
4910
4900
4959
5011
5007
4912
5073
5141
5157
5237
5176
5173
5192
5242
5184
5263
5219
5333
5473
5438
5445
5620
5563
5563
5556
5605
5661
5647
5719
5737
5778
5802
5895
5968
5882
5845
6015
6027
6130
6113
6157
6254
6165
6310
6518
6541
6735
6619
6617
6758
6980
7208
7195
7240
7280
7456
7478
7700
7790
8056
8131
8239
8352
8564
8563
8751
8935
8995
9192
9434
9624
9815
9998
10067
10382
10526
10634
10938
11185
11410
11584
11895
12271
12291
12485
12890
13203
13238
13326
13667
14212
14330
14471
14562
14846
15055
15123
15236
15336
15539
15603
15822
15928
16006
16018
15989
16060
16123
16188
16214
16164
15967
15962
15946
15700
15660
15517
15170
15089
15019
14907
14566
14405
14006
13754
13515
13228
13101
12802
12528
12142
11748
11544
11332
10955
10652
10352
10232
9945
9736
9276
8980
8605
8508
8227
7914
7726
7470
7266
7225
7021
6661
6381
6393
6107
5973
5743
5565
5495
5390
5235
5152
5088
4935
4880
4661
4527
4458
4392
4335
4242
4054
3948
3908
3874
3835
3753
3707
3554
3517
3604
3522
3518
3371
3300
3286
3246
3195
3192
3161
3085
2993
2992
2976
2957
2924
2882
2890
2834
2806
2809
2732
2814
2852
2743
2811
2805
2803
2765
2753
2739
2738
2708
2740
2753
2783
2831
2881
2888
2961
3011
3033
3092
3156
3287
3364
3428
3523
3640
3750
3914
4001
4107
4303
4427
4634
4793
4838
5108
5302
5525
5721
6015
6120
6344
6503
6631
6791
7036
7075
7245
7444
7507
7432
7658
7627
7644
7829
7939
7865
7832
7876
7997
8008
7925
7960
7994
7869
8003
7867
7916
7900
7882
7936
7788
7866
8005
7948
7896
7902
7986
7955
7974
7992
7937
7931
7877
7895
7767
7639
7604
7524
7489
7557
7407
7248
7191
7085
6913
6892
6659
6413
6378
6049
5967
5833
5600
5521
5329
5197
5092
5021
4992
4973
4972
4963
5044
5077
5208
5304
5432
5524
5785
6005
6231
6468
6686
6975
7156
7485
7693
7841
8025
8262
8406
8418
8684
9140
9167
9302
9411
9499
9459
9551
9589
9606
9638
9451
9480
9372
9264
9042
8853
8596
8281
8059
7620
7372
7025
6655
6197
5962
5626
5249
4772
4371
4127
3738
3382
2961
2749
2534
2383
2194
1974
1844
1710
1605
1534
1459
1393
1462
1495
1449
1502
1555
1602
1679
1746
1831
1978
1987
2037
2173
2274
2366
2451
2489
2577
2588
2708
2803
2825
2840
2910
2949
2925
2927
2945
2975
3055
3088
3155
3112
3162
3253
3194
3220
3171
3192
3251
3316
3320
3245
3196
3217
3299
3341
3317
3377
3358
3386
3360
3367
3372
3350
3366
3375
3232
3253
3347
3347
3285
3237
3233
3300
3213
3157
3130
3115
3117
3126
3046
3019
2982
2983
3028
3053
3085
2969
2978
2907
2935
2919
2942
2924
2908
2879
2898
2946
2974
2913
2859
2939
2906
3036
2986
2921
3010
3070
3075
3016
3106
3211
3320
3310
3382
3428
3457
3637
3685
3797
3830
3856
3954
4105
4172
4259
4247
4411
4427
4646
4691
4859
4911
4833
4747
4828
4953
4951
4888
4830
4792
4672
4640
4575
4481
4426
4390
4155
3992
3936
3810
3640
3565
3496
3409
3366
3342
3260
3227
3146
3152
3192
3247
3286
3335
3326
3429
3523
3568
3655
3643
3673
3721
3702
3680
3631
3580
3520
3465
3460
3269
3155
3004
2753
2617
2488
2363
2147
1888
1736
1543
1358
1213
1113
956
847
706
589
520
482
396
324
271
224
204
158
140
130
114
107
102
100
98
80
85
83
77
76
81
70
76
70
56
72
71
59
61
69
73
65
63
60
65
60
64
65
58
54
55
63
63
61
48
53
58
54
58
64
64
52
57
52
47
49
54
53
55
56
51
54
52
58
57
54
58
52
56
51
53
51
54
49
40
46
44
49
57
51
52
57
55
51
40
39
57
41
36
38
34
41
39
40
43
54
47
38
end of experiment