File: src/parser/__tests__/data/single_sample.vms
VAMAS Surface Chemical Analysis Standard Data Transfer Format 1988 May 4
Not specified
MI-600-BE9240AA
DESKTOP-MI6NA2R\kratos
20200909_AK_PVK_UPS.experiment
4
Casa Info Follows CasaXPS Version 2.3.22PR1.0
0
SourceAnalyserAngle: 54.735600 d
CasaRowLabel:AK_control
NORM
REGULAR
9
4
Index
d
PositionX [mm]
n
PositionY [mm]
n
PositionZ [mm]
n
0
0
0
0
9
wide
AK_control
2020
9
9
13
28
32
2
41
Casa Info Follows
0
0
0
0
Creation
Created by : DESKTOP-MI6NA2R\kratos
Date created : 09/09/2020 13:28
Computer : DESKTOP-MI6NA2R
Location
Location ID : AK_control
Sample : AK_control
Description : (25.507,20.108,-3.724)mm
Tilt : 0.00
Charge Neutraliser : Off
Settings
Excitation
Mode : XPS - monochromatic
Tuning : Spectroscopy
Emission current : 15.00mA
Anode library : Al
ESCA modes
Collimation : Slot
Lens : Hybrid
Resolution : 160.00
Scan
Deflection : (0.000, 0.000)mm
wide : 286.690-1491.690eV, Sweeps 1
Start : 286.690eV
End : 1491.690eV
Centre : 889.190eV
Width : 1205.000eV
Step size : 1.000eV
Number Steps : 1205
Dwell time : 100ms
Sweep time : 120s
Sweeps : 1
Instrument Conditions
Work function : -4.50
Acquisition Conditions
X-ray Power : 225.00W
XPS
1
25.5065
20.1084
-3.72434
Al (mono)
1486.69
225
1e+037
1e+037
1e+037
1e+037
FAT
160
1e+037
-4.5
1e+037
1e+037
1e+037
1e+037
1e+037
wide

-1
Kinetic energy
eV
286.69
1
2
Intensity
d
Transmission
d
pulse counting
0.0995025
0
1e+037
0
0
12.1975
2808
2885
2916
2948
2868
2915
2844
2977
2996
2937
2853
2830
2878
2910
2937
2909
2943
2961
2987
2994
3067
3011
2981
2938
2938
3114
3038
2998
3016
3033
3046
3037
3001
3063
3081
3075
3095
3092
3097
3071
3192
3171
3018
3078
3136
3148
3099
3116
3146
3199
3205
3202
3187
3174
3098
3140
3199
3191
3190
3195
3199
3210
3203
3308
3214
3167
3281
3249
3200
3282
3208
3228
3256
3274
3356
3306
3348
3357
3301
3286
3333
3426
3465
3449
3384
3423
3473
3348
3409
3333
3390
3344
3405
3356
3373
3398
3412
3394
3333
3335
3363
3374
3395
3438
3355
3396
3416
3417
3378
3418
3484
3467
3459
3453
3482
3575
3437
3456
3537
3533
3482
3473
3516
3457
3430
3485
3622
3685
3595
3571
3543
3459
3471
3475
3469
3439
3419
3359
3461
3477
3482
3447
3464
3442
3348
3315
3374
3382
3276
3354
3347
3187
3114
3133
3026
3207
3238
3269
3187
3123
3099
3072
2941
2994
3112
3018
3010
3060
3039
3145
3070
3062
3103
3116
3185
3217
3184
3197
3212
3225
3235
3279
3233
3279
3379
3380
3292
3401
3419
3370
3416
3396
3369
3427
3517
3468
3495
3524
3555
3521
3602
3541
3629
3638
3675
3701
3731
3782
3900
3765
3664
3793
3814
3820
3787
3883
3863
3786
4059
4515
4588
4413
4432
4318
4084
3654
3345
3207
3121
3099
3543
4022
3705
3260
3123
2827
2718
2689
2618
2601
2638
2680
2590
2538
2591
2550
2569
2640
2669
2616
2635
2657
2659
2702
2660
2770
2706
2603
2712
2711
2621
2729
2638
2654
2701
2729
2831
3011
3224
3295
3182
2965
2870
2733
2715
2737
2590
2571
2512
2453
2482
2574
2619
2657
2591
2564
2534
2598
2565
2558
2565
2492
2498
2542
2511
2587
2664
2592
2462
2572
2578
2623
2599
2647
2650
2723
2781
2706
2746
2693
2701
2681
2644
2651
2646
2694
2631
2605
2608
2589
2712
2754
2920
3153
3507
3739
3525
3175
2779
2531
2382
2329
2270
2242
2221
2238
2280
2199
2167
2236
2222
2185
2143
2168
2146
2189
2161
2206
2280
2227
2153
2254
2203
2156
2182
2180
2244
2211
2235
2228
2180
2238
2203
2260
2209
2211
2190
2210
2182
2233
2224
2253
2283
2262
2263
2237
2223
2294
2301
2305
2284
2256
2324
2341
2289
2309
2312
2322
2364
2362
2388
2306
2326
2367
2325
2357
2369
2415
2349
2361
2316
2337
2406
2396
2468
2373
2367
2379
2315
2426
2379
2448
2422
2438
2395
2387
2390
2404
2376
2383
2415
2426
2508
2504
2568
2495
2414
2451
2422
2472
2495
2530
2549
2536
2444
2568
2590
2567
2514
2488
2489
2527
2555
2552
2521
2611
2533
2542
2588
2563
2518
2565
2579
2654
2653
2510
2596
2538
2554
2527
2580
2589
2583
2619
2627
2658
2579
2643
2728
2676
2652
2556
2558
2636
2609
2671
2651
2632
2702
2659
2593
2568
2641
2696
2671
2700
2638
2648
2683
2651
2698
2613
2760
2694
2678
2686
2724
2743
2766
2766
2724
2737
2714
2699
2738
2745
2784
2803
2854
2806
2817
2836
2825
2812
2801
2788
2814
2985
2882
2940
2947
2884
2973
2996
3003
3005
2956
3006
3097
3093
3117
3133
3107
3127
3173
3317
3289
3322
3344
3313
3430
3331
3372
3496
3523
3446
3568
3619
3641
3633
3710
3790
3938
3972
4124
4112
4075
4012
3915
3749
3669
3503
3467
3485
3616
3612
3743
4225
6911
10415
6384
3140
2646
2458
2303
2216
2268
2221
2442
4455
10642
10902
3557
1650
1327
1280
1198
1134
1118
1144
1122
1106
1129
1104
1145
1147
1101
1088
1089
1122
1102
1153
1091
1084
1066
1077
1094
1079
1099
1075
1075
1061
1062
1105
1112
1090
1090
1107
1086
1087
1108
1120
1100
1115
1110
1113
1113
1166
1111
1135
1171
1158
1181
1124
1157
1174
1127
1103
1152
1135
1174
1217
1169
1138
1164
1171
1207
1182
1193
1181
1190
1226
1175
1164
1205
1226
1199
1194
1264
1136
1165
1243
1250
1215
1239
1217
1248
1244
1201
1171
1223
1236
1211
1236
1261
1238
1222
1193
1160
1190
1214
1248
1256
1279
1253
1263
1231
1264
1286
1284
1280
1229
1228
1231
1268
1296
1330
1303
1282
1310
1306
1261
1241
1283
1283
1256
1280
1371
1340
1347
1327
1276
1309
1355
1348
1335
1305
1301
1338
1340
1339
1390
1381
1367
1421
1432
1338
1382
1389
1415
1358
1392
1432
1421
1370
1397
1471
1523
1511
1402
1427
1521
1502
1540
1568
1565
1539
1567
1541
1543
1552
1504
1547
1532
1583
1583
1598
1628
1588
1643
1695
1735
1874
2120
2092
2074
1819
1708
1568
1529
1487
1429
1452
1477
1432
1408
1400
1400
1419
1431
1455
1442
1478
1597
1813
2012
2252
2135
1778
1480
1292
1190
1118
1044
1003
973
965
1010
1111
1368
1171
929
926
925
873
891
865
877
910
922
963
933
916
917
939
872
863
912
928
900
915
924
919
938
921
947
929
957
938
916
921
928
948
903
913
936
919
920
916
926
901
935
999
986
961
936
948
977
947
977
988
937
908
957
970
986
975
966
969
977
1003
1026
1078
1008
983
1033
1015
1007
985
996
992
988
959
1002
1011
1052
1030
1046
1064
973
1031
1089
1069
1073
1082
1055
1095
1069
1091
1048
1062
1033
1061
1021
1020
1050
1069
1037
1050
1062
1073
1116
1132
1106
1093
1043
1100
1068
1082
1093
1141
1232
1180
1113
1140
1225
1165
1113
1095
1176
1143
1141
1161
1090
1119
1176
1152
1131
1138
1163
1177
1169
1175
1164
1134
1149
1168
1195
1123
1218
1229
1182
1222
1185
1185
1211
1275
1246
1218
1248
1197
1235
1208
1206
1235
1203
1224
1219
1252
1186
1228
1272
1225
1234
1270
1242
1271
1264
1309
1268
1310
1287
1248
1221
1236
1301
1333
1336
1276
1280
1296
1335
1312
1331
1336
1390
1343
1399
1284
1392
1414
1388
1404
1389
1361
1394
1365
1443
1450
1457
1487
1472
1505
1417
1461
1450
1439
1499
1554
1408
1513
1612
1664
1748
1717
1629
1495
1509
1515
1547
1503
1499
1580
1529
1566
1558
1577
1603
1625
1592
1638
1699
1727
1754
1811
1800
1770
1829
1878
1970
1948
1956
1976
1988
1913
1929
1904
1863
1924
1984
1919
1872
1799
1856
2063
2661
4437
4134
1955
1751
2707
5059
3982
1455
1104
1036
960
871
889
880
856
877
885
820
912
906
947
1023
990
867
714
607
593
614
566
545
598
584
580
612
633
641
619
621
634
594
594
639
618
636
600
602
627
624
646
677
667
667
650
676
700
717
674
720
774
780
759
723
723
717
702
703
688
700
716
729
805
742
744
818
788
809
808
787
841
830
844
807
755
741
717
637
610
616
551
568
576
859
1815
3018
3041
2567
689
316
250
256
215
226
243
233
233
240
238
239
221
258
252
222
203
212
211
222
230
252
242
235
319
551
653
496
781
525
161
114
115
110
100
99
75
53
63
53
42
44
98
174
233
229
98
14
4
2
0
1
0
0
15.5208
I3d
AK_control
2020
9
9
14
52
56
2
43
Casa Info Follows
0
0
0
0
Creation
Created by : DESKTOP-MI6NA2R\kratos
Date created : 09/09/2020 14:52
Computer : DESKTOP-MI6NA2R
Location
Location ID : AK_control
Sample : AK_control
Description : (25.507,20.108,-3.910)mm
Tilt : 0.00
Charge Neutraliser : Off
Settings
Excitation
Mode : XPS - monochromatic
Tuning : Spectroscopy
Emission current : 10.00mA
Anode library : Al
ESCA modes
Collimation : Slot
Lens : Hybrid
Resolution : 40.00
Scan
Deflection : (0.000, 0.000)mm
I3d : 851.690-871.690eV, Sweeps 2
Start : 851.690eV
End : 871.690eV
Centre : 861.690eV
Width : 20.000eV
Step size : 0.200eV
Number Steps : 100
Dwell time : 594ms
Sweep time : 60s
Sweeps : 2
Target quality : 200
Instrument Conditions
Work function : -4.50
Acquisition Conditions
X-ray Power : 150.00W
Quality : 123.76
XPS
3
25.5065
20.1084
-3.9102
Al (mono)
1486.69
150
1e+037
1e+037
1e+037
1e+037
FAT
40
1e+037
-4.5
1e+037
1e+037
1e+037
1e+037
1e+037
I3d

-1
Kinetic energy
eV
851.69
0.2
2
Intensity
d
Transmission
d
pulse counting
0.59387
2
0
1e+037
1e+037
1e+037
0
202
30594
503435
2.21742
2.22459
84957
2.22459
84747
2.22452
84478
2.22444
84532
2.22437
84527
2.22429
84447
2.22421
84871
2.22414
84978
2.22406
85512
2.22399
86530
2.22391
88314
2.22384
91661
2.22376
97089
2.22369
107178
2.22361
125472
2.22353
157830
2.22346
209501
2.22338
280455
2.22331
353701
2.22323
396976
2.22316
383928
2.22308
322878
2.22301
241760
2.22293
172531
2.22285
127712
2.22278
102472
2.2227
88974
2.22263
81313
2.22255
75741
2.22248
72272
2.2224
69498
2.22233
67111
2.22225
65773
2.22217
64731
2.2221
63823
2.22202
63041
2.22195
62430
2.22187
61774
2.2218
60995
2.22172
59812
2.22165
58521
2.22157
57379
2.22149
55912
2.22142
55000
2.22134
53917
2.22127
53373
2.22119
53044
2.22112
52758
2.22104
52314
2.22097
51756
2.22089
51876
2.22081
51498
2.22074
50992
2.22066
51222
2.22059
50685
2.22051
50108
2.22044
49790
2.22036
49501
2.22029
49146
2.22021
48688
2.22013
48056
2.22006
48072
2.21998
48009
2.21991
47524
2.21983
47565
2.21976
48136
2.21968
49190
2.21961
51336
2.21953
55557
2.21946
62521
2.21938
74552
2.2193
95867
2.21923
134061
2.21915
197903
2.21908
290886
2.219
399804
2.21893
484834
2.21885
503435
2.21878
441056
2.2187
331139
2.21862
222952
2.21855
144614
2.21847
98488
2.2184
72996
2.21832
59225
2.21825
51120
2.21817
46064
2.2181
42673
2.21802
39812
2.21794
38154
2.21787
36849
2.21779
35580
2.21772
34543
2.21766
33559
2.21763
32863
2.2176
32511
2.21757
31881
2.21754
31434
2.21751
31036
2.21748
31164
2.21745
30594
2.21742
Pb4f
AK_control
2020
9
9
14
52
56
2
43
Casa Info Follows
0
0
0
0
Creation
Created by : DESKTOP-MI6NA2R\kratos
Date created : 09/09/2020 14:52
Computer : DESKTOP-MI6NA2R
Location
Location ID : AK_control
Sample : AK_control
Description : (25.507,20.108,-3.910)mm
Tilt : 0.00
Charge Neutraliser : Off
Settings
Excitation
Mode : XPS - monochromatic
Tuning : Spectroscopy
Emission current : 10.00mA
Anode library : Al
ESCA modes
Collimation : Slot
Lens : Hybrid
Resolution : 40.00
Scan
Deflection : (0.000, 0.000)mm
Pb4f : 1336.690-1356.690eV, Sweeps 2
Start : 1336.690eV
End : 1356.690eV
Centre : 1346.690eV
Width : 20.000eV
Step size : 0.200eV
Number Steps : 100
Dwell time : 594ms
Sweep time : 60s
Sweeps : 2
Target quality : 200
Instrument Conditions
Work function : -4.50
Acquisition Conditions
X-ray Power : 150.00W
Quality : 90.30
XPS
4
25.5065
20.1084
-3.9102
Al (mono)
1486.69
150
1e+037
1e+037
1e+037
1e+037
FAT
40
1e+037
-4.5
1e+037
1e+037
1e+037
1e+037
1e+037
Pb4f

-1
Kinetic energy
eV
1336.69
0.2
2
Intensity
d
Transmission
d
pulse counting
0.59387
2
0
1e+037
1e+037
1e+037
0
202
13403
157183
2.11422
2.1278
31169
2.1278
30912
2.12766
30999
2.12752
31033
2.12738
30760
2.12724
30412
2.1271
29894
2.12696
29842
2.12681
29364
2.12667
29119
2.12653
28807
2.12639
28710
2.12625
28794
2.12611
28688
2.12597
28794
2.12583
28771
2.12569
28912
2.12554
29464
2.1254
29719
2.12526
29840
2.12512
29968
2.12498
30515
2.12484
30383
2.1247
30652
2.12456
31182
2.12442
32671
2.12427
35563
2.12413
41835
2.12399
54164
2.12385
75259
2.12371
104247
2.12357
128106
2.12343
129368
2.12329
105465
2.12315
72669
2.12301
48598
2.12286
36390
2.12272
31682
2.12258
30432
2.12244
31504
2.1223
32413
2.12216
31086
2.12202
27652
2.12188
24460
2.12174
22843
2.12159
22386
2.12145
22572
2.12131
22801
2.12117
23506
2.12103
24944
2.12089
27770
2.12075
33657
2.12061
46522
2.12047
70446
2.12032
106403
2.12018
144106
2.12004
157183
2.1199
133175
2.11976
90718
2.11962
54939
2.11948
35317
2.11934
27646
2.1192
25616
2.11905
26775
2.11891
28889
2.11877
28828
2.11863
25035
2.11849
20335
2.11835
17532
2.11821
16258
2.11807
15850
2.11793
15545
2.11778
15060
2.11764
15000
2.1175
14959
2.11736
14823
2.11722
14518
2.11708
14479
2.11694
14360
2.1168
14302
2.11666
14186
2.11652
14196
2.11637
14234
2.11623
14195
2.11609
14139
2.11595
14183
2.11581
14163
2.11567
13969
2.11553
13915
2.11539
13953
2.11525
13872
2.1151
13630
2.11496
13781
2.11482
13805
2.11468
13650
2.11454
13663
2.1144
13675
2.11426
13590
2.11422
13511
2.11432
13403
2.11442
13577
2.11452
O1s
AK_control
2020
9
9
14
52
56
2
43
Casa Info Follows
0
0
0
0
Creation
Created by : DESKTOP-MI6NA2R\kratos
Date created : 09/09/2020 14:52
Computer : DESKTOP-MI6NA2R
Location
Location ID : AK_control
Sample : AK_control
Description : (25.507,20.108,-3.910)mm
Tilt : 0.00
Charge Neutraliser : Off
Settings
Excitation
Mode : XPS - monochromatic
Tuning : Spectroscopy
Emission current : 10.00mA
Anode library : Al
ESCA modes
Collimation : Slot
Lens : Hybrid
Resolution : 40.00
Scan
Deflection : (0.000, 0.000)mm
O1s : 943.690-963.690eV, Sweeps 4
Start : 943.690eV
End : 963.690eV
Centre : 953.690eV
Width : 20.000eV
Step size : 0.200eV
Number Steps : 100
Dwell time : 594ms
Sweep time : 60s
Sweeps : 4
Target quality : 200
Instrument Conditions
Work function : -4.50
Acquisition Conditions
X-ray Power : 150.00W
Quality : 21.05
XPS
5
25.5065
20.1084
-3.9102
Al (mono)
1486.69
150
1e+037
1e+037
1e+037
1e+037
FAT
40
1e+037
-4.5
1e+037
1e+037
1e+037
1e+037
1e+037
O1s

-1
Kinetic energy
eV
943.69
0.2
2
Intensity
d
Transmission
d
pulse counting
0.59387
4
0
1e+037
1e+037
1e+037
0
202
59772
63394
2.19692
2.20238
60018
2.20238
60355
2.20232
60241
2.20227
59785
2.20221
60391
2.20216
60198
2.2021
59778
2.20205
60028
2.20199
59842
2.20194
60124
2.20188
60013
2.20183
60190
2.20178
59772
2.20172
59955
2.20167
60308
2.20161
60283
2.20156
60269
2.2015
60237
2.20145
60052
2.20139
60480
2.20134
60591
2.20128
60028
2.20123
60241
2.20117
60257
2.20112
60069
2.20107
60228
2.20101
60517
2.20096
60652
2.2009
60721
2.20085
60383
2.20079
60060
2.20074
60479
2.20068
60686
2.20063
60830
2.20057
60605
2.20052
60533
2.20046
60558
2.20041
60732
2.20036
60737
2.2003
60892
2.20025
60623
2.20019
61426
2.20014
62120
2.20008
62448
2.20003
62441
2.19997
62422
2.19992
62735
2.19986
63254
2.19981
62973
2.19975
63286
2.1997
63394
2.19965
62951
2.19959
62433
2.19954
62128
2.19948
61916
2.19943
61254
2.19937
61136
2.19932
61213
2.19926
61049
2.19921
60834
2.19915
61043
2.1991
60808
2.19905
61051
2.19899
61093
2.19894
61326
2.19888
60734
2.19883
60925
2.19877
61223
2.19872
61258
2.19866
60892
2.19861
60723
2.19855
60860
2.1985
60730
2.19844
60900
2.19839
60729
2.19834
60584
2.19828
60976
2.19823
61227
2.19817
61292
2.19812
61113
2.19806
61136
2.19801
61016
2.19795
61530
2.1979
60968
2.19784
61083
2.19779
61169
2.19773
61068
2.19768
61378
2.19763
61098
2.19757
61410
2.19752
61494
2.19746
61187
2.19741
61287
2.19735
61413
2.1973
61367
2.19724
61377
2.19719
61338
2.19713
61758
2.19708
61635
2.19702
61348
2.19697
61500
2.19692
N1s
AK_control
2020
9
9
14
52
56
2
43
Casa Info Follows
0
0
0
0
Creation
Created by : DESKTOP-MI6NA2R\kratos
Date created : 09/09/2020 14:52
Computer : DESKTOP-MI6NA2R
Location
Location ID : AK_control
Sample : AK_control
Description : (25.507,20.108,-3.910)mm
Tilt : 0.00
Charge Neutraliser : Off
Settings
Excitation
Mode : XPS - monochromatic
Tuning : Spectroscopy
Emission current : 10.00mA
Anode library : Al
ESCA modes
Collimation : Slot
Lens : Hybrid
Resolution : 40.00
Scan
Deflection : (0.000, 0.000)mm
N1s : 1076.690-1096.690eV, Sweeps 4
Start : 1076.690eV
End : 1096.690eV
Centre : 1086.690eV
Width : 20.000eV
Step size : 0.200eV
Number Steps : 100
Dwell time : 594ms
Sweep time : 60s
Sweeps : 4
Target quality : 200
Instrument Conditions
Work function : -4.50
Acquisition Conditions
X-ray Power : 150.00W
Quality : 123.58
XPS
6
25.5065
20.1084
-3.9102
Al (mono)
1486.69
150
1e+037
1e+037
1e+037
1e+037
FAT
40
1e+037
-4.5
1e+037
1e+037
1e+037
1e+037
1e+037
N1s

-1
Kinetic energy
eV
1076.69
0.2
2
Intensity
d
Transmission
d
pulse counting
0.59387
4
0
1e+037
1e+037
1e+037
0
202
42865
78692
2.17079
2.17314
60907
2.17079
59923
2.17081
58516
2.17083
58115
2.17086
57064
2.17088
56275
2.1709
55493
2.17093
54682
2.17095
53807
2.17097
52812
2.171
52118
2.17102
51435
2.17104
51446
2.17107
50706
2.17109
50197
2.17112
49707
2.17114
49548
2.17116
48674
2.17119
48727
2.17121
48376
2.17123
48355
2.17126
48031
2.17128
47841
2.1713
47563
2.17133
47282
2.17135
47154
2.17137
47093
2.1714
47014
2.17142
46634
2.17144
46523
2.17147
46698
2.17149
46384
2.17151
46357
2.17154
46122
2.17156
46057
2.17159
46142
2.17161
46321
2.17163
46514
2.17166
46973
2.17168
48307
2.1717
51005
2.17173
55728
2.17175
61584
2.17177
68659
2.1718
75917
2.17182
78692
2.17184
75628
2.17187
66760
2.17189
57319
2.17191
50532
2.17194
47182
2.17196
46098
2.17199
44934
2.17201
44583
2.17203
44540
2.17206
44309
2.17208
44096
2.1721
43808
2.17213
44226
2.17215
43825
2.17217
43724
2.1722
43680
2.17222
43790
2.17224
43961
2.17227
43937
2.17229
43650
2.17231
43213
2.17234
43668
2.17236
43693
2.17238
43636
2.17241
43167
2.17243
43539
2.17246
43673
2.17248
43376
2.1725
43564
2.17253
43403
2.17255
43320
2.17257
43105
2.1726
43456
2.17262
43432
2.17264
43423
2.17267
43361
2.17269
43328
2.17271
43497
2.17274
43516
2.17276
43336
2.17278
43241
2.17281
43467
2.17283
43397
2.17285
43133
2.17288
43149
2.1729
43192
2.17293
43349
2.17295
42865
2.17297
43235
2.173
43240
2.17302
43161
2.17304
43197
2.17307
42879
2.17309
43334
2.17311
43467
2.17314
C 1s
AK_control
2020
9
9
14
52
56
2
43
Casa Info Follows
0
0
0
0
Creation
Created by : DESKTOP-MI6NA2R\kratos
Date created : 09/09/2020 14:52
Computer : DESKTOP-MI6NA2R
Location
Location ID : AK_control
Sample : AK_control
Description : (25.507,20.108,-3.910)mm
Tilt : 0.00
Charge Neutraliser : Off
Settings
Excitation
Mode : XPS - monochromatic
Tuning : Spectroscopy
Emission current : 10.00mA
Anode library : Al
ESCA modes
Collimation : Slot
Lens : Hybrid
Resolution : 40.00
Scan
Deflection : (0.000, 0.000)mm
C 1s : 1186.690-1206.690eV, Sweeps 4
Start : 1186.690eV
End : 1206.690eV
Centre : 1196.690eV
Width : 20.000eV
Step size : 0.200eV
Number Steps : 100
Dwell time : 594ms
Sweep time : 60s
Sweeps : 4
Target quality : 200
Instrument Conditions
Work function : -4.50
Acquisition Conditions
X-ray Power : 150.00W
Quality : 57.70
XPS
7
25.5065
20.1084
-3.9102
Al (mono)
1486.69
150
1e+037
1e+037
1e+037
1e+037
FAT
40
1e+037
-4.5
1e+037
1e+037
1e+037
1e+037
1e+037
C
1s
-1
Kinetic energy
eV
1186.69
0.2
2
Intensity
d
Transmission
d
pulse counting
0.593895
4
0
1e+037
1e+037
1e+037
0
202
47017
57772
2.14722
2.15025
47358
2.14817
47072
2.14811
47121
2.14805
47461
2.148
47223
2.14794
47017
2.14788
47644
2.14782
47534
2.14776
47229
2.1477
47582
2.14764
47499
2.14759
47801
2.14753
47944
2.14747
48153
2.14741
47670
2.14735
47827
2.14729
47659
2.14724
47660
2.14722
47558
2.14726
47386
2.14729
47486
2.14733
47493
2.14737
47435
2.1474
47165
2.14744
47410
2.14748
47355
2.14751
47324
2.14755
47332
2.14758
47201
2.14762
47452
2.14766
47440
2.14769
47372
2.14773
47343
2.14777
47603
2.1478
47696
2.14784
47344
2.14788
47475
2.14791
47539
2.14795
47577
2.14799
47636
2.14802
47533
2.14806
47655
2.1481
47707
2.14813
47090
2.14817
47421
2.1482
47947
2.14824
47783
2.14828
47958
2.14831
48297
2.14835
48646
2.14839
49144
2.14842
49528
2.14846
50338
2.1485
51720
2.14853
53786
2.14857
56056
2.14861
57772
2.14864
57312
2.14868
54770
2.14872
51953
2.14875
50060
2.14879
48979
2.14882
48909
2.14886
49324
2.1489
49653
2.14893
49484
2.14897
49589
2.14901
49528
2.14904
49474
2.14908
49660
2.14912
50199
2.14915
50884
2.14919
51932
2.14923
51883
2.14926
52428
2.1493
52209
2.14934
50998
2.14937
50341
2.14941
49322
2.14944
48388
2.14948
47945
2.14952
47718
2.14955
47534
2.14959
47440
2.14963
47594
2.14966
47331
2.1497
47698
2.14974
47805
2.14977
47479
2.14981
47663
2.14985
47657
2.14988
47673
2.14992
47580
2.14996
47395
2.14999
47184
2.15003
47625
2.15007
47755
2.1501
47726
2.15014
47400
2.15017
47445
2.15021
47707
2.15025
S 2p
AK_control
2020
9
9
14
52
56
2
43
Casa Info Follows
0
0
0
0
Creation
Created by : DESKTOP-MI6NA2R\kratos
Date created : 09/09/2020 14:52
Computer : DESKTOP-MI6NA2R
Location
Location ID : AK_control
Sample : AK_control
Description : (25.507,20.108,-3.910)mm
Tilt : 0.00
Charge Neutraliser : Off
Settings
Excitation
Mode : XPS - monochromatic
Tuning : Spectroscopy
Emission current : 10.00mA
Anode library : Al
ESCA modes
Collimation : Slot
Lens : Hybrid
Resolution : 40.00
Scan
Deflection : (0.000, 0.000)mm
S 2p : 1311.690-1331.690eV, Sweeps 4
Start : 1311.690eV
End : 1331.690eV
Centre : 1321.690eV
Width : 20.000eV
Step size : 0.200eV
Number Steps : 100
Dwell time : 594ms
Sweep time : 60s
Sweeps : 4
Target quality : 200
Instrument Conditions
Work function : -4.50
Acquisition Conditions
X-ray Power : 150.00W
Quality : 68.47
XPS
8
25.5065
20.1084
-3.9102
Al (mono)
1486.69
150
1e+037
1e+037
1e+037
1e+037
FAT
40
1e+037
-4.5
1e+037
1e+037
1e+037
1e+037
1e+037
S
2p
-1
Kinetic energy
eV
1311.69
0.2
2
Intensity
d
Transmission
d
pulse counting
0.59387
4
0
1e+037
1e+037
1e+037
0
202
55091
66342
2.13133
2.14544
55111
2.14544
55091
2.1453
55336
2.14516
55371
2.14501
55272
2.14487
55389
2.14473
55119
2.14459
55497
2.14445
55644
2.14431
55901
2.14417
55593
2.14403
55780
2.14389
55476
2.14374
55183
2.1436
56197
2.14346
55962
2.14332
56091
2.14318
56040
2.14304
56110
2.1429
56247
2.14276
56377
2.14262
56469
2.14248
56321
2.14233
56558
2.14219
56422
2.14205
56792
2.14191
56960
2.14177
56968
2.14163
57149
2.14149
57260
2.14135
57150
2.14121
57250
2.14106
57488
2.14092
57781
2.14078
57948
2.14064
58137
2.1405
58447
2.14036
58536
2.14022
58393
2.14008
59048
2.13994
59104
2.13979
59419
2.13965
59518
2.13951
60176
2.13937
60410
2.13923
60468
2.13909
60330
2.13895
60310
2.13881
60488
2.13867
60418
2.13852
60493
2.13838
60591
2.13824
60977
2.1381
61068
2.13796
60937
2.13782
61635
2.13768
61423
2.13754
61598
2.1374
62002
2.13725
61676
2.13711
62003
2.13697
62431
2.13683
62723
2.13669
63019
2.13655
63528
2.13641
64357
2.13627
64359
2.13613
64132
2.13599
64754
2.13584
65214
2.1357
65572
2.13556
65241
2.13542
64768
2.13528
64582
2.13514
65256
2.135
65270
2.13486
65667
2.13472
65890
2.13457
65557
2.13443
65265
2.13429
65195
2.13415
65269
2.13401
65555
2.13387
65922
2.13373
65783
2.13359
65600
2.13345
65859
2.1333
66342
2.13316
66030
2.13302
66025
2.13288
66244
2.13274
65840
2.1326
65636
2.13246
65732
2.13232
65497
2.13218
65291
2.13203
65366
2.13189
64854
2.13175
65086
2.13161
65187
2.13147
64967
2.13133
VBM
AK_control
2020
9
9
15
40
1
2
38
Casa Info Follows
0
0
0
0
Creation
Created by : DESKTOP-MI6NA2R\kratos
Date created : 09/09/2020 15:40
Computer : DESKTOP-MI6NA2R
Location
Location ID : AK_control
Sample : AK_control
Description : (25.507,20.108,-3.910)mm
Tilt : 0.00
Charge Neutraliser : Off
Settings
Excitation
Mode : UPS
Tuning : HeI
ESCA modes
Collimation : Slot
Lens : UPS
Resolution : 10.00
Scan
Deflection : (0.000, 0.000)mm
HeI : 15.220-22.220eV, Sweeps 1
Start : 15.220eV
End : 22.220eV
Centre : 18.720eV
Width : 7.000eV
Step size : 0.025eV
Number Steps : 280
Dwell time : 214ms
Sweep time : 60s
Sweeps : 1
Instrument Conditions
Work function : -4.50
Sample bias : 9.11
XPS
9
25.5065
20.1084
-3.9102
Not specified
21.22
1e+037
1e+037
1e+037
1e+037
1e+037
FAT
10
1e+037
-4.5
9.11
1e+037
1e+037
1e+037
1e+037
HeI VBM

-1
Kinetic energy
eV
15.22
0.025
2
Intensity
d
Transmission
d
pulse counting
0.213523
1
0
1e+037
1e+037
1e+037
0
562
0
10062
1
1
7761
1
7826
1
8130
1
8229
1
8309
1
8328
1
8666
1
8721
1
8988
1
8950
1
9104
1
9225
1
9358
1
9475
1
9566
1
9624
1
9735
1
9731
1
9922
1
9732
1
9899
1
9882
1
9874
1
9932
1
9998
1
9956
1
10013
1
9957
1
9904
1
10062
1
10057
1
9955
1
9834
1
9772
1
9924
1
9841
1
9877
1
9685
1
9513
1
9607
1
9748
1
9555
1
9402
1
9355
1
9603
1
9371
1
9091
1
9142
1
9206
1
9124
1
9021
1
8931
1
8863
1
8852
1
8641
1
8532
1
8372
1
8218
1
8224
1
8137
1
8002
1
7913
1
8059
1
7840
1
7899
1
8108
1
7840
1
7832
1
7719
1
7640
1
7802
1
7913
1
7891
1
7938
1
7956
1
8030
1
8025
1
7990
1
8042
1
8197
1
8182
1
8141
1
8226
1
8334
1
8314
1
8300
1
8274
1
8384
1
8263
1
8379
1
8450
1
8366
1
8343
1
8348
1
8405
1
8332
1
8245
1
8255
1
8204
1
8090
1
8154
1
8020
1
7970
1
7947
1
7822
1
7678
1
7614
1
7661
1
7622
1
7521
1
7327
1
7146
1
7046
1
6904
1
6712
1
6684
1
6503
1
6387
1
6309
1
6076
1
6043
1
5873
1
5775
1
5667
1
5375
1
5283
1
5176
1
5024
1
4877
1
4772
1
4679
1
4513
1
4352
1
4287
1
4156
1
4133
1
3990
1
3896
1
3783
1
3660
1
3608
1
3416
1
3369
1
3332
1
3174
1
3091
1
2964
1
2818
1
2589
1
2542
1
2354
1
2213
1
1999
1
1882
1
1758
1
1580
1
1450
1
1337
1
1245
1
1130
1
958
1
874
1
827
1
708
1
631
1
545
1
496
1
426
1
361
1
336
1
327
1
272
1
257
1
231
1
181
1
157
1
156
1
147
1
131
1
137
1
118
1
113
1
112
1
103
1
94
1
91
1
91
1
91
1
96
1
83
1
75
1
84
1
88
1
83
1
68
1
81
1
74
1
68
1
70
1
65
1
65
1
57
1
53
1
53
1
64
1
67
1
65
1
55
1
65
1
56
1
53
1
58
1
47
1
41
1
52
1
40
1
44
1
59
1
38
1
49
1
42
1
40
1
42
1
40
1
50
1
45
1
31
1
38
1
34
1
30
1
28
1
34
1
25
1
32
1
36
1
25
1
22
1
29
1
25
1
24
1
15
1
14
1
10
1
14
1
12
1
9
1
7
1
9
1
13
1
4
1
9
1
6
1
6
1
4
1
4
1
5
1
3
1
4
1
4
1
3
1
5
1
3
1
3
1
3
1
10
1
6
1
1
1
1
1
3
1
1
1
2
1
7
1
1
1
0
1
1
1
1
1
2
1
0
1
1
1
1
1
1
1
SECO
AK_control
2020
9
9
15
50
4
2
38
Casa Info Follows
0
0
0
0
Creation
Created by : DESKTOP-MI6NA2R\kratos
Date created : 09/09/2020 15:50
Computer : DESKTOP-MI6NA2R
Location
Location ID : AK_control
Sample : AK_control
Description : (25.507,20.108,-3.910)mm
Tilt : 0.00
Charge Neutraliser : Off
Settings
Excitation
Mode : UPS
Tuning : HeI
ESCA modes
Collimation : 55 um Aperture
Lens : UPS
Resolution : 10.00
Scan
Deflection : (0.000, 0.000)mm
HeI : 1.220-24.220eV, Sweeps 1
Start : 1.220eV
End : 24.220eV
Centre : 12.720eV
Width : 23.000eV
Step size : 0.025eV
Number Steps : 920
Dwell time : 65ms
Sweep time : 60s
Sweeps : 1
Instrument Conditions
Work function : -4.50
Sample bias : 9.11
XPS
10
25.5065
20.1084
-3.9102
Not specified
21.22
1e+037
1e+037
1e+037
1e+037
1e+037
FAT
10
1e+037
-4.5
9.11
1e+037
1e+037
1e+037
1e+037
HeI SECO

-1
Kinetic energy
eV
1.22
0.025
2
Intensity
d
Transmission
d
pulse counting
0.065147
0
1e+037
0
0
1
3
4
5
1
3
7
6
6
2
4
2
2
2
2
4
2
3
1
0
2
5
3
2
3
1
0
1
3
3
3
2
1
1
3
2
3
4
2
1
5
3
5
3
3
6
6
3
3
3
5
2
4
3
2
4
2
7
7
1
3
5
3
3
9
6
3
5
6
9
10
8
10
11
6
7
6
9
8
9
11
8
9
13
10
11
12
5
7
15
12
15
17
10
13
17
11
12
12
13
15
13
11
18
16
14
21
25
26
14
15
24
21
29
32
36
57
82
116
167
246
387
673
1014
1357
1517
1648
1694
1742
1697
1666
1668
1624
1612
1564
1500
1531
1524
1483
1458
1483
1398
1392
1379
1320
1277
1262
1250
1199
1209
1187
1181
1145
1148
1050
1029
1035
1029
952
961
1009
1006
965
969
938
924
889
901
896
948
906
894
856
852
866
867
883
848
817
826
815
827
807
774
744
762
764
789
781
722
772
739
734
730
728
723
699
684
704
685
692
698
654
668
668
646
678
647
604
640
672
620
613
640
588
643
614
632
620
601
594
600
623
596
607
571
564
538
535
537
548
551
512
536
538
514
524
491
514
506
515
477
489
548
477
507
478
481
473
460
498
460
448
446
462
478
446
406
431
423
436
421
394
379
388
393
396
403
374
388
364
352
349
326
335
339
352
331
325
335
292
273
291
283
310
305
292
295
282
275
255
278
287
262
256
259
258
234
238
246
245
226
230
236
244
211
215
224
224
252
224
209
219
212
202
212
198
202
186
194
209
187
195
204
200
190
207
197
193
209
189
195
213
182
184
185
194
174
181
175
186
175
172
165
187
170
152
149
182
140
154
172
170
160
166
159
163
165
154
162
153
148
150
148
158
159
145
125
139
133
122
133
141
134
141
121
137
134
144
137
141
146
137
135
127
132
130
117
114
118
149
136
127
121
119
122
140
121
129
127
136
148
125
129
131
127
139
121
140
119
130
136
117
128
135
131
123
137
135
119
127
108
118
137
126
116
104
108
105
128
122
108
115
126
123
113
119
139
137
119
115
109
116
116
111
108
89
111
92
102
119
101
103
101
89
119
102
95
101
92
99
87
88
100
86
116
99
89
84
99
106
93
102
93
94
106
104
90
89
89
109
88
80
86
88
80
83
86
80
71
76
80
86
98
78
75
78
74
84
80
89
70
66
59
79
75
74
90
65
66
73
73
60
64
66
63
72
74
76
70
58
64
59
64
67
68
70
59
70
73
69
64
72
59
57
68
77
72
67
73
80
68
68
53
64
77
61
60
68
75
60
69
70
67
74
68
70
59
60
60
62
75
77
91
79
79
78
77
92
96
84
89
87
97
96
102
95
99
107
94
105
96
92
94
113
117
102
95
94
90
92
99
103
113
106
98
95
87
100
108
102
102
71
77
96
97
96
102
107
103
84
97
106
94
88
85
86
90
80
83
89
87
81
85
81
80
77
81
82
81
83
77
90
85
76
82
82
89
78
87
87
91
82
84
85
82
105
107
91
87
85
89
90
92
81
99
80
95
104
97
88
90
90
96
95
87
79
76
91
77
72
88
90
80
76
85
71
74
77
73
78
65
61
69
61
65
70
63
71
60
51
45
60
40
52
52
41
46
41
37
44
43
33
48
38
24
34
36
27
26
26
22
30
21
28
29
22
21
12
13
8
11
10
5
8
8
11
9
4
4
5
5
5
3
3
2
2
2
0
1
2
1
0
0
0
0
1
0
1
1
1
0
1
2
2
0
1
0
0
1
1
1
0
0
0
0
0
0
1
1
1
1
1
0
0
0
1
0
0
1
0
0
0
0
0
0
0
0
0
0
0
0
0
0
0
0
0
0
0
0
0
0
0
0
0
0
0
0
0
0
0
1
0
0
0
0
0
0
0
0
0
0
0
0
0
0
0
0
0
0
0
0
0
0
0
0
0
0
0
0
0
0
0
0
0
0
0
0
0
0
0
0
0
0
0
0
0
0
0
0
0
0
0
0
0
0
0
0
0
0
0
0
0
0
0
0
0
0
0
0
0
0
0
0
0
0
0
0
0
0
0
0
0
0
0
0
0
0
0
0
0
0
0
0
0
0
0
0
0
0
0
0
0
0
0
0
0
0
0
0
0
0
1
end of experiment